Workbook

Sheet INSTRUCCIONES
B1: REGISTRO DE ENSAYOS A COMPRESIÓN POR LOTE — BLOCK ROCHELL
B3: HOJAS
B4: LOTES | C4: Una fila por día de producción por máquina y producto. Fecha + Máquina + Producto → N° de LOTE automático (ej. 8070325P1). Repetido = rojo → usa "Secuencia" (8070325P1-2).
B5: Trazabilidad | C5: Columnas azules: diseño de mezcla, cemento, horas de curado, unidades producidas. Llénalas para poder explicar lotes bajos.
B6: Resultados | C6: Resumen automático: probetas, edades, promedio, mín/máx, CV, estimado a 28 d, CUMPLE y ALERTAS (pocas probetas, CV alto, absorción alta, sin rotura a 28 d).
B7: ENSAYOS | C7: Una fila por probeta rota. Eliges el lote; producto, máquina, fecha y edad salen solos. Registra condición del bloque (seco/húmedo) y tipo de falla.
B8: ABSORCION | C8: Una fila por bloque: pesos saturado, sumergido y seco → absorción (kg/m³ y %), densidad, clase y comparación con ASTM C90.
B9: CURVA EDAD | C9: Factores de resistencia por edad. Arranca con factores sacados de tu histórico general (amarillo) y se reemplazan por los tuyos cuando rompas lotes a temprana edad y a 28 d.
B10: CONTROL | C10: Gráfico de control de los últimos lotes por máquina y producto (media ±2σ y spec), y comparación P1 vs P2 vs P3.
B11: CERTIFICADO | C11: Eliges el lote (y opcionalmente la fecha de rotura) → formato ASTM C140 numerado (CR-lote-fecha), listo para imprimir/PDF.
B12: CONFIG | C12: Máquinas, productos y requisitos a 28 d, clientes, obras, listas, datos del equipo, límites de absorción y parámetros de control.
B13: Colores | C13: Amarillo con texto azul = lo que tú llenas. Texto negro = fórmula. Azul claro = N° de lote generado.
B14: Protección | C14: LOTES, ENSAYOS, ABSORCION, CURVA EDAD, CONTROL y CERTIFICADO están protegidas SIN contraseña para que no se borren fórmulas: solo se editan las celdas amarillas. Para cambiar algo: Revisar → Desproteger hoja.
B16: PLAN DE ENSAYO SUGERIDO
B17: Rutina | C17: Por lote: mínimo 3 bloques a compresión (ASTM C140) a la edad de despacho.
B18: Curva | C18: Al menos 1 lote por máquina al mes: 3 bloques a 3 d + 3 a 7 d + 3 a 28 d del MISMO lote.
B19: Absorción | C19: Al menos 1 vez al mes por máquina y producto: 3 bloques del mismo lote.
B21: HISTÓRICO MIGRADO
B22: Importado | C22: 42 lotes y 216 probetas de ENSAYO_ROTURAS.xlsx (sep-2024 a nov-2025).
B23: Normalizado | C23: Códigos fuera de formato (P18121124, P28201224, 140125P1, 030225P2…) convertidos al estándar; B1/B2/B3 → P1/P2/P3. El código original queda en LOTES col. G.
B24: No importado | C24: Hojas sin N° de lote: LOPESAN 6-12-24, P2 T3.5, P2 T 2.5, CEMEX 260525, LOPESAN 270525 (4). Duplicada idéntica descartada: LOPESAN 170225 8 (duplicada).
B25: Corregido | C25: Medidas "19.5.5" tomadas como 19.5. Fecha de rotura faltante tomada del encabezado de la hoja. Bloques con nota "húmedos" marcados como Húmedo.
B27: PENDIENTE DE TI
B28: CONFIG | C28: Poner el requisito mínimo a 28 días por producto (sin eso CUMPLE dice "Sin spec"), el % de área neta si lo tienes, y tus diseños de mezcla y cementos.

Sheet LOTES
A1: REGISTRO DE LOTES
A2: Llena Fecha, Máquina y Producto → el N° de LOTE se genera solo: [código producto][DDMMAA][máquina][-secuencia opcional]. Ej: 8 + 070325 + P1 = 8070325P1
H3: TRAZABILIDAD DE PRODUCCIÓN | M3: RESULTADOS DE ENSAYO | U3: ESTIMACIÓN A 28 DÍAS Y CUMPLIMIENTO | AD3: ABSORCIÓN
A4: N° | B4: Fecha producción | C4: Máquina | D4: Producto | E4: Secuencia (opcional) | F4: N° LOTE | G4: Código original (histórico) | H4: Diseño de mezcla | I4: Cemento | J4: Horas de curado | K4: Unidades producidas | L4: Notas de producción | M4: N° probetas | N4: Edad mín (d) | O4: Edad máx (d) | P4: Promedio ensayado (kg/cm²) | Q4: Mínimo (kg/cm²) | R4: Máximo (kg/cm²) | S4: Desv. est. | T4: CV % | U4: Prom. edad temprana | V4: Prom. a 28 d | W4: Factor del lote (temp./28d) | X4: Factor usado | Y4: Resist. 28 d (real o est.) | Z4: Mín. 28 d (real o est.) | AA4: Spec prom. | AB4: Spec indiv. | AC4: CUMPLE | AD4: Absorción prom. (kg/m³) | AE4: Densidad prom. (kg/m³) | AF4: Absorción máx. (kg/m³) | AG4: ALERTAS | AH4: aux ctrl | AI4: aux P²
A5: =IF(B5="","",ROW()-4) -> 1 | B5: 45551 | C5: P1 | D5: Block 8" | F5: =IF(OR(B5="",C5="",D5=""),"",IFERROR(INDEX(CONFIG!$E$5:$E$14,MATCH(D5,CONFIG!$D$5:$D$14,0)),"?")&RIGHT("0"&DAY(B5),2)&RIGHT("0"&MONTH(B5),2)&RIGHT(YEAR(B5),2)&C5&IF(E5="","","-"&E5)) -> 8160924P1 | M5: =IF(F5="","",COUNTIFS(ENSAYOS!$C$5:$C$3004,F5,ENSAYOS!$Q$5:$Q$3004,">0")) -> 5 | N5: =IF(N(M5)=0,"",_xlfn.MINIFS(ENSAYOS!$G$5:$G$3004,ENSAYOS!$C$5:$C$3004,F5,ENSAYOS!$Q$5:$Q$3004,">0")) -> 3 | O5: =IF(N(M5)=0,"",_xlfn.MAXIFS(ENSAYOS!$G$5:$G$3004,ENSAYOS!$C$5:$C$3004,F5,ENSAYOS!$Q$5:$Q$3004,">0")) -> 3 | P5: =IF(N(M5)=0,"",AVERAGEIFS(ENSAYOS!$Q$5:$Q$3004,ENSAYOS!$C$5:$C$3004,F5,ENSAYOS!$Q$5:$Q$3004,">0")) -> 77.159594 | Q5: =IF(N(M5)=0,"",_xlfn.MINIFS(ENSAYOS!$Q$5:$Q$3004,ENSAYOS!$C$5:$C$3004,F5,ENSAYOS!$Q$5:$Q$3004,">0")) -> 57.12431 | R5: =IF(N(M5)=0,"",_xlfn.MAXIFS(ENSAYOS!$Q$5:$Q$3004,ENSAYOS!$C$5:$C$3004,F5,ENSAYOS!$Q$5:$Q$3004,">0")) -> 98.365953 | S5: =IF(N(M5)<2,"",SQRT(MAX(0,(SUMIFS(ENSAYOS!$X$5:$X$3004,ENSAYOS!$C$5:$C$3004,F5,ENSAYOS!$Q$5:$Q$3004,">0")-M5*P5^2)/(M5-1)))) -> 14.824071 | T5: =IF(S5="","",S5/P5) -> 0.19212219 | U5: =IF(N(M5)=0,"",IF(N5>=CONFIG!$B$27,"",AVERAGEIFS(ENSAYOS!$Q$5:$Q$3004,ENSAYOS!$C$5:$C$3004,F5,ENSAYOS!$Q$5:$Q$3004,">0",ENSAYOS!$G$5:$G$3004,N5))) -> 77.159594 | V5: =IF(N(M5)=0,"",IF(COUNTIFS(ENSAYOS!$C$5:$C$3004,F5,ENSAYOS!$Q$5:$Q$3004,">0",ENSAYOS!$G$5:$G$3004,">="&CONFIG!$B$27)=0,"",AVERAGEIFS(ENSAYOS!$Q$5:$Q$3004,ENSAYOS!$C$5:$C$3004,F5,ENSAYOS!$Q$5:$Q$3004,">0",ENSAYOS!$G$5:$G$3004,">="&CONFIG!$B$27))) | W5: =IF(AND(U5<>"",V5<>""),U5/V5,"") | X5: =IF(U5="","",INDEX('CURVA EDAD'!$E$5:$E$32,MIN(28,MAX(1,N5)))) -> 0.84 | Y5: =IF(V5<>"",V5,IF(U5="","",U5/X5)) -> 91.85666 | Z5: =IF(V5<>"",_xlfn.MINIFS(ENSAYOS!$Q$5:$Q$3004,ENSAYOS!$C$5:$C$3004,F5,ENSAYOS!$Q$5:$Q$3004,">0",ENSAYOS!$G$5:$G$3004,">="&CONFIG!$B$27),IF(U5="","",_xlfn.MINIFS(ENSAYOS!$Q$5:$Q$3004,ENSAYOS!$C$5:$C$3004,F5,ENSAYOS!$Q$5:$Q$3004,">0",ENSAYOS!$G$5:$G$3004,N5)/X5)) -> 68.005131 | AA5: =IF(D5="","",IFERROR(1/(1/INDEX(CONFIG!$J$5:$J$14,MATCH(D5,CONFIG!$D$5:$D$14,0))),"")) | AB5: =IF(D5="","",IFERROR(1/(1/INDEX(CONFIG!$K$5:$K$14,MATCH(D5,CONFIG!$D$5:$D$14,0))),"")) | AC5: =IF(N(M5)=0,"",IF(AA5="","Sin spec",IF(AND(Y5>=AA5,OR(AB5="",Z5>=AB5)),"CUMPLE","NO CUMPLE")&IF(V5=""," (est.)",""))) -> Sin spec | AD5: =IF(F5="","",IF(COUNTIFS(ABSORCION!$C$5:$C$1004,F5,ABSORCION!$I$5:$I$1004,">0")=0,"",AVERAGEIFS(ABSORCION!$I$5:$I$1004,ABSORCION!$C$5:$C$1004,F5,ABSORCION!$I$5:$I$1004,">0"))) | AE5: =IF(F5="","",IF(COUNTIFS(ABSORCION!$C$5:$C$1004,F5,ABSORCION!$I$5:$I$1004,">0")=0,"",AVERAGEIFS(ABSORCION!$K$5:$K$1004,ABSORCION!$C$5:$C$1004,F5,ABSORCION!$I$5:$I$1004,">0"))) | AF5: =IF(AE5="","",IF(AE5>=CONFIG!$E$21,CONFIG!$F$21,IF(AE5>=CONFIG!$E$20,CONFIG!$F$20,CONFIG!$F$19))) | AG5: =IF(F5="","",TRIM(IF(N(M5)=0,"Sin ensayos. ","")&IF(AND(N(M5)>0,N(M5)<CONFIG!$B$26),"Menos de "&CONFIG!$B$26&" probetas. ","")&IF(N(T5)>CONFIG!$B$25,"CV alto. ","")&IF(AND(N(AD5)>0,N(AD5)>N(AF5)),"Absorción alta. ",""))) -> CV alto. | AH5: =IF(AND(N(M5)>0,OR(CONTROL!$C$4="TODAS",C5=CONTROL!$C$4),D5=CONTROL!$C$5),MAX($AH$4:AH4)+1,"") -> 1 | AI5: =IF(AH5="","",P5^2) -> 5953.603
A6: =IF(B6="","",ROW()-4) -> 2 | B6: 45608 | C6: P1 | D6: Block 8" | F6: =IF(OR(B6="",C6="",D6=""),"",IFERROR(INDEX(CONFIG!$E$5:$E$14,MATCH(D6,CONFIG!$D$5:$D$14,0)),"?")&RIGHT("0"&DAY(B6),2)&RIGHT("0"&MONTH(B6),2)&RIGHT(YEAR(B6),2)&C6&IF(E6="","","-"&E6)) -> 8121124P1 | G6: P18121124 | M6: =IF(F6="","",COUNTIFS(ENSAYOS!$C$5:$C$3004,F6,ENSAYOS!$Q$5:$Q$3004,">0")) -> 6 | N6: =IF(N(M6)=0,"",_xlfn.MINIFS(ENSAYOS!$G$5:$G$3004,ENSAYOS!$C$5:$C$3004,F6,ENSAYOS!$Q$5:$Q$3004,">0")) -> 28 | O6: =IF(N(M6)=0,"",_xlfn.MAXIFS(ENSAYOS!$G$5:$G$3004,ENSAYOS!$C$5:$C$3004,F6,ENSAYOS!$Q$5:$Q$3004,">0")) -> 28 | P6: =IF(N(M6)=0,"",AVERAGEIFS(ENSAYOS!$Q$5:$Q$3004,ENSAYOS!$C$5:$C$3004,F6,ENSAYOS!$Q$5:$Q$3004,">0")) -> 80.39749 | Q6: =IF(N(M6)=0,"",_xlfn.MINIFS(ENSAYOS!$Q$5:$Q$3004,ENSAYOS!$C$5:$C$3004,F6,ENSAYOS!$Q$5:$Q$3004,">0")) -> 71.744239 | R6: =IF(N(M6)=0,"",_xlfn.MAXIFS(ENSAYOS!$Q$5:$Q$3004,ENSAYOS!$C$5:$C$3004,F6,ENSAYOS!$Q$5:$Q$3004,">0")) -> 92.737423 | S6: =IF(N(M6)<2,"",SQRT(MAX(0,(SUMIFS(ENSAYOS!$X$5:$X$3004,ENSAYOS!$C$5:$C$3004,F6,ENSAYOS!$Q$5:$Q$3004,">0")-M6*P6^2)/(M6-1)))) -> 7.8269927 | T6: =IF(S6="","",S6/P6) -> 0.097353694 | U6: =IF(N(M6)=0,"",IF(N6>=CONFIG!$B$27,"",AVERAGEIFS(ENSAYOS!$Q$5:$Q$3004,ENSAYOS!$C$5:$C$3004,F6,ENSAYOS!$Q$5:$Q$3004,">0",ENSAYOS!$G$5:$G$3004,N6))) | V6: =IF(N(M6)=0,"",IF(COUNTIFS(ENSAYOS!$C$5:$C$3004,F6,ENSAYOS!$Q$5:$Q$3004,">0",ENSAYOS!$G$5:$G$3004,">="&CONFIG!$B$27)=0,"",AVERAGEIFS(ENSAYOS!$Q$5:$Q$3004,ENSAYOS!$C$5:$C$3004,F6,ENSAYOS!$Q$5:$Q$3004,">0",ENSAYOS!$G$5:$G$3004,">="&CONFIG!$B$27))) -> 80.39749 | W6: =IF(AND(U6<>"",V6<>""),U6/V6,"") | X6: =IF(U6="","",INDEX('CURVA EDAD'!$E$5:$E$32,MIN(28,MAX(1,N6)))) | Y6: =IF(V6<>"",V6,IF(U6="","",U6/X6)) -> 80.39749 | Z6: =IF(V6<>"",_xlfn.MINIFS(ENSAYOS!$Q$5:$Q$3004,ENSAYOS!$C$5:$C$3004,F6,ENSAYOS!$Q$5:$Q$3004,">0",ENSAYOS!$G$5:$G$3004,">="&CONFIG!$B$27),IF(U6="","",_xlfn.MINIFS(ENSAYOS!$Q$5:$Q$3004,ENSAYOS!$C$5:$C$3004,F6,ENSAYOS!$Q$5:$Q$3004,">0",ENSAYOS!$G$5:$G$3004,N6)/X6)) -> 71.744239 | AA6: =IF(D6="","",IFERROR(1/(1/INDEX(CONFIG!$J$5:$J$14,MATCH(D6,CONFIG!$D$5:$D$14,0))),"")) | AB6: =IF(D6="","",IFERROR(1/(1/INDEX(CONFIG!$K$5:$K$14,MATCH(D6,CONFIG!$D$5:$D$14,0))),"")) | AC6: =IF(N(M6)=0,"",IF(AA6="","Sin spec",IF(AND(Y6>=AA6,OR(AB6="",Z6>=AB6)),"CUMPLE","NO CUMPLE")&IF(V6=""," (est.)",""))) -> Sin spec | AD6: =IF(F6="","",IF(COUNTIFS(ABSORCION!$C$5:$C$1004,F6,ABSORCION!$I$5:$I$1004,">0")=0,"",AVERAGEIFS(ABSORCION!$I$5:$I$1004,ABSORCION!$C$5:$C$1004,F6,ABSORCION!$I$5:$I$1004,">0"))) | AE6: =IF(F6="","",IF(COUNTIFS(ABSORCION!$C$5:$C$1004,F6,ABSORCION!$I$5:$I$1004,">0")=0,"",AVERAGEIFS(ABSORCION!$K$5:$K$1004,ABSORCION!$C$5:$C$1004,F6,ABSORCION!$I$5:$I$1004,">0"))) | AF6: =IF(AE6="","",IF(AE6>=CONFIG!$E$21,CONFIG!$F$21,IF(AE6>=CONFIG!$E$20,CONFIG!$F$20,CONFIG!$F$19))) | AG6: =IF(F6="","",TRIM(IF(N(M6)=0,"Sin ensayos. ","")&IF(AND(N(M6)>0,N(M6)<CONFIG!$B$26),"Menos de "&CONFIG!$B$26&" probetas. ","")&IF(N(T6)>CONFIG!$B$25,"CV alto. ","")&IF(AND(N(AD6)>0,N(AD6)>N(AF6)),"Absorción alta. ",""))) | AH6: =IF(AND(N(M6)>0,OR(CONTROL!$C$4="TODAS",C6=CONTROL!$C$4),D6=CONTROL!$C$5),MAX($AH$4:AH5)+1,"") -> 2 | AI6: =IF(AH6="","",P6^2) -> 6463.7564
A7: =IF(B7="","",ROW()-4) -> 3 | B7: 45612 | C7: P1 | D7: Block 8" | F7: =IF(OR(B7="",C7="",D7=""),"",IFERROR(INDEX(CONFIG!$E$5:$E$14,MATCH(D7,CONFIG!$D$5:$D$14,0)),"?")&RIGHT("0"&DAY(B7),2)&RIGHT("0"&MONTH(B7),2)&RIGHT(YEAR(B7),2)&C7&IF(E7="","","-"&E7)) -> 8161124P1 | M7: =IF(F7="","",COUNTIFS(ENSAYOS!$C$5:$C$3004,F7,ENSAYOS!$Q$5:$Q$3004,">0")) -> 8 | N7: =IF(N(M7)=0,"",_xlfn.MINIFS(ENSAYOS!$G$5:$G$3004,ENSAYOS!$C$5:$C$3004,F7,ENSAYOS!$Q$5:$Q$3004,">0")) -> 3 | O7: =IF(N(M7)=0,"",_xlfn.MAXIFS(ENSAYOS!$G$5:$G$3004,ENSAYOS!$C$5:$C$3004,F7,ENSAYOS!$Q$5:$Q$3004,">0")) -> 3 | P7: =IF(N(M7)=0,"",AVERAGEIFS(ENSAYOS!$Q$5:$Q$3004,ENSAYOS!$C$5:$C$3004,F7,ENSAYOS!$Q$5:$Q$3004,">0")) -> 84.48048 | Q7: =IF(N(M7)=0,"",_xlfn.MINIFS(ENSAYOS!$Q$5:$Q$3004,ENSAYOS!$C$5:$C$3004,F7,ENSAYOS!$Q$5:$Q$3004,">0")) -> 67.846303 | R7: =IF(N(M7)=0,"",_xlfn.MAXIFS(ENSAYOS!$Q$5:$Q$3004,ENSAYOS!$C$5:$C$3004,F7,ENSAYOS!$Q$5:$Q$3004,">0")) -> 98.30708 | S7: =IF(N(M7)<2,"",SQRT(MAX(0,(SUMIFS(ENSAYOS!$X$5:$X$3004,ENSAYOS!$C$5:$C$3004,F7,ENSAYOS!$Q$5:$Q$3004,">0")-M7*P7^2)/(M7-1)))) -> 9.3898859 | T7: =IF(S7="","",S7/P7) -> 0.11114859 | U7: =IF(N(M7)=0,"",IF(N7>=CONFIG!$B$27,"",AVERAGEIFS(ENSAYOS!$Q$5:$Q$3004,ENSAYOS!$C$5:$C$3004,F7,ENSAYOS!$Q$5:$Q$3004,">0",ENSAYOS!$G$5:$G$3004,N7))) -> 84.48048 | V7: =IF(N(M7)=0,"",IF(COUNTIFS(ENSAYOS!$C$5:$C$3004,F7,ENSAYOS!$Q$5:$Q$3004,">0",ENSAYOS!$G$5:$G$3004,">="&CONFIG!$B$27)=0,"",AVERAGEIFS(ENSAYOS!$Q$5:$Q$3004,ENSAYOS!$C$5:$C$3004,F7,ENSAYOS!$Q$5:$Q$3004,">0",ENSAYOS!$G$5:$G$3004,">="&CONFIG!$B$27))) | W7: =IF(AND(U7<>"",V7<>""),U7/V7,"") | X7: =IF(U7="","",INDEX('CURVA EDAD'!$E$5:$E$32,MIN(28,MAX(1,N7)))) -> 0.84 | Y7: =IF(V7<>"",V7,IF(U7="","",U7/X7)) -> 100.572 | Z7: =IF(V7<>"",_xlfn.MINIFS(ENSAYOS!$Q$5:$Q$3004,ENSAYOS!$C$5:$C$3004,F7,ENSAYOS!$Q$5:$Q$3004,">0",ENSAYOS!$G$5:$G$3004,">="&CONFIG!$B$27),IF(U7="","",_xlfn.MINIFS(ENSAYOS!$Q$5:$Q$3004,ENSAYOS!$C$5:$C$3004,F7,ENSAYOS!$Q$5:$Q$3004,">0",ENSAYOS!$G$5:$G$3004,N7)/X7)) -> 80.769408 | AA7: =IF(D7="","",IFERROR(1/(1/INDEX(CONFIG!$J$5:$J$14,MATCH(D7,CONFIG!$D$5:$D$14,0))),"")) | AB7: =IF(D7="","",IFERROR(1/(1/INDEX(CONFIG!$K$5:$K$14,MATCH(D7,CONFIG!$D$5:$D$14,0))),"")) | AC7: =IF(N(M7)=0,"",IF(AA7="","Sin spec",IF(AND(Y7>=AA7,OR(AB7="",Z7>=AB7)),"CUMPLE","NO CUMPLE")&IF(V7=""," (est.)",""))) -> Sin spec | AD7: =IF(F7="","",IF(COUNTIFS(ABSORCION!$C$5:$C$1004,F7,ABSORCION!$I$5:$I$1004,">0")=0,"",AVERAGEIFS(ABSORCION!$I$5:$I$1004,ABSORCION!$C$5:$C$1004,F7,ABSORCION!$I$5:$I$1004,">0"))) | AE7: =IF(F7="","",IF(COUNTIFS(ABSORCION!$C$5:$C$1004,F7,ABSORCION!$I$5:$I$1004,">0")=0,"",AVERAGEIFS(ABSORCION!$K$5:$K$1004,ABSORCION!$C$5:$C$1004,F7,ABSORCION!$I$5:$I$1004,">0"))) | AF7: =IF(AE7="","",IF(AE7>=CONFIG!$E$21,CONFIG!$F$21,IF(AE7>=CONFIG!$E$20,CONFIG!$F$20,CONFIG!$F$19))) | AG7: =IF(F7="","",TRIM(IF(N(M7)=0,"Sin ensayos. ","")&IF(AND(N(M7)>0,N(M7)<CONFIG!$B$26),"Menos de "&CONFIG!$B$26&" probetas. ","")&IF(N(T7)>CONFIG!$B$25,"CV alto. ","")&IF(AND(N(AD7)>0,N(AD7)>N(AF7)),"Absorción alta. ",""))) | AH7: =IF(AND(N(M7)>0,OR(CONTROL!$C$4="TODAS",C7=CONTROL!$C$4),D7=CONTROL!$C$5),MAX($AH$4:AH6)+1,"") -> 3 | AI7: =IF(AH7="","",P7^2) -> 7136.9516
A8: =IF(B8="","",ROW()-4) -> 4 | B8: 45646 | C8: P2 | D8: Block 6" | F8: =IF(OR(B8="",C8="",D8=""),"",IFERROR(INDEX(CONFIG!$E$5:$E$14,MATCH(D8,CONFIG!$D$5:$D$14,0)),"?")&RIGHT("0"&DAY(B8),2)&RIGHT("0"&MONTH(B8),2)&RIGHT(YEAR(B8),2)&C8&IF(E8="","","-"&E8)) -> 6201224P2 | G8: P28201224 | M8: =IF(F8="","",COUNTIFS(ENSAYOS!$C$5:$C$3004,F8,ENSAYOS!$Q$5:$Q$3004,">0")) -> 8 | N8: =IF(N(M8)=0,"",_xlfn.MINIFS(ENSAYOS!$G$5:$G$3004,ENSAYOS!$C$5:$C$3004,F8,ENSAYOS!$Q$5:$Q$3004,">0")) -> 22 | O8: =IF(N(M8)=0,"",_xlfn.MAXIFS(ENSAYOS!$G$5:$G$3004,ENSAYOS!$C$5:$C$3004,F8,ENSAYOS!$Q$5:$Q$3004,">0")) -> 22 | P8: =IF(N(M8)=0,"",AVERAGEIFS(ENSAYOS!$Q$5:$Q$3004,ENSAYOS!$C$5:$C$3004,F8,ENSAYOS!$Q$5:$Q$3004,">0")) -> 75.919904 | Q8: =IF(N(M8)=0,"",_xlfn.MINIFS(ENSAYOS!$Q$5:$Q$3004,ENSAYOS!$C$5:$C$3004,F8,ENSAYOS!$Q$5:$Q$3004,">0")) -> 65.089481 | R8: =IF(N(M8)=0,"",_xlfn.MAXIFS(ENSAYOS!$Q$5:$Q$3004,ENSAYOS!$C$5:$C$3004,F8,ENSAYOS!$Q$5:$Q$3004,">0")) -> 87.477957 | S8: =IF(N(M8)<2,"",SQRT(MAX(0,(SUMIFS(ENSAYOS!$X$5:$X$3004,ENSAYOS!$C$5:$C$3004,F8,ENSAYOS!$Q$5:$Q$3004,">0")-M8*P8^2)/(M8-1)))) -> 9.7441829 | T8: =IF(S8="","",S8/P8) -> 0.1283482 | U8: =IF(N(M8)=0,"",IF(N8>=CONFIG!$B$27,"",AVERAGEIFS(ENSAYOS!$Q$5:$Q$3004,ENSAYOS!$C$5:$C$3004,F8,ENSAYOS!$Q$5:$Q$3004,">0",ENSAYOS!$G$5:$G$3004,N8))) -> 75.919904 | V8: =IF(N(M8)=0,"",IF(COUNTIFS(ENSAYOS!$C$5:$C$3004,F8,ENSAYOS!$Q$5:$Q$3004,">0",ENSAYOS!$G$5:$G$3004,">="&CONFIG!$B$27)=0,"",AVERAGEIFS(ENSAYOS!$Q$5:$Q$3004,ENSAYOS!$C$5:$C$3004,F8,ENSAYOS!$Q$5:$Q$3004,">0",ENSAYOS!$G$5:$G$3004,">="&CONFIG!$B$27))) | W8: =IF(AND(U8<>"",V8<>""),U8/V8,"") | X8: =IF(U8="","",INDEX('CURVA EDAD'!$E$5:$E$32,MIN(28,MAX(1,N8)))) -> 0.983 | Y8: =IF(V8<>"",V8,IF(U8="","",U8/X8)) -> 77.232863 | Z8: =IF(V8<>"",_xlfn.MINIFS(ENSAYOS!$Q$5:$Q$3004,ENSAYOS!$C$5:$C$3004,F8,ENSAYOS!$Q$5:$Q$3004,">0",ENSAYOS!$G$5:$G$3004,">="&CONFIG!$B$27),IF(U8="","",_xlfn.MINIFS(ENSAYOS!$Q$5:$Q$3004,ENSAYOS!$C$5:$C$3004,F8,ENSAYOS!$Q$5:$Q$3004,">0",ENSAYOS!$G$5:$G$3004,N8)/X8)) -> 66.215138 | AA8: =IF(D8="","",IFERROR(1/(1/INDEX(CONFIG!$J$5:$J$14,MATCH(D8,CONFIG!$D$5:$D$14,0))),"")) | AB8: =IF(D8="","",IFERROR(1/(1/INDEX(CONFIG!$K$5:$K$14,MATCH(D8,CONFIG!$D$5:$D$14,0))),"")) | AC8: =IF(N(M8)=0,"",IF(AA8="","Sin spec",IF(AND(Y8>=AA8,OR(AB8="",Z8>=AB8)),"CUMPLE","NO CUMPLE")&IF(V8=""," (est.)",""))) -> Sin spec | AD8: =IF(F8="","",IF(COUNTIFS(ABSORCION!$C$5:$C$1004,F8,ABSORCION!$I$5:$I$1004,">0")=0,"",AVERAGEIFS(ABSORCION!$I$5:$I$1004,ABSORCION!$C$5:$C$1004,F8,ABSORCION!$I$5:$I$1004,">0"))) | AE8: =IF(F8="","",IF(COUNTIFS(ABSORCION!$C$5:$C$1004,F8,ABSORCION!$I$5:$I$1004,">0")=0,"",AVERAGEIFS(ABSORCION!$K$5:$K$1004,ABSORCION!$C$5:$C$1004,F8,ABSORCION!$I$5:$I$1004,">0"))) | AF8: =IF(AE8="","",IF(AE8>=CONFIG!$E$21,CONFIG!$F$21,IF(AE8>=CONFIG!$E$20,CONFIG!$F$20,CONFIG!$F$19))) | AG8: =IF(F8="","",TRIM(IF(N(M8)=0,"Sin ensayos. ","")&IF(AND(N(M8)>0,N(M8)<CONFIG!$B$26),"Menos de "&CONFIG!$B$26&" probetas. ","")&IF(N(T8)>CONFIG!$B$25,"CV alto. ","")&IF(AND(N(AD8)>0,N(AD8)>N(AF8)),"Absorción alta. ",""))) | AH8: =IF(AND(N(M8)>0,OR(CONTROL!$C$4="TODAS",C8=CONTROL!$C$4),D8=CONTROL!$C$5),MAX($AH$4:AH7)+1,"") | AI8: =IF(AH8="","",P8^2)
A9: =IF(B9="","",ROW()-4) -> 5 | B9: 45646 | C9: P1 | D9: Block 8" | F9: =IF(OR(B9="",C9="",D9=""),"",IFERROR(INDEX(CONFIG!$E$5:$E$14,MATCH(D9,CONFIG!$D$5:$D$14,0)),"?")&RIGHT("0"&DAY(B9),2)&RIGHT("0"&MONTH(B9),2)&RIGHT(YEAR(B9),2)&C9&IF(E9="","","-"&E9)) -> 8201224P1 | G9: 201224P1 | M9: =IF(F9="","",COUNTIFS(ENSAYOS!$C$5:$C$3004,F9,ENSAYOS!$Q$5:$Q$3004,">0")) -> 9 | N9: =IF(N(M9)=0,"",_xlfn.MINIFS(ENSAYOS!$G$5:$G$3004,ENSAYOS!$C$5:$C$3004,F9,ENSAYOS!$Q$5:$Q$3004,">0")) -> 34 | O9: =IF(N(M9)=0,"",_xlfn.MAXIFS(ENSAYOS!$G$5:$G$3004,ENSAYOS!$C$5:$C$3004,F9,ENSAYOS!$Q$5:$Q$3004,">0")) -> 34 | P9: =IF(N(M9)=0,"",AVERAGEIFS(ENSAYOS!$Q$5:$Q$3004,ENSAYOS!$C$5:$C$3004,F9,ENSAYOS!$Q$5:$Q$3004,">0")) -> 85.03646 | Q9: =IF(N(M9)=0,"",_xlfn.MINIFS(ENSAYOS!$Q$5:$Q$3004,ENSAYOS!$C$5:$C$3004,F9,ENSAYOS!$Q$5:$Q$3004,">0")) -> 65.908471 | R9: =IF(N(M9)=0,"",_xlfn.MAXIFS(ENSAYOS!$Q$5:$Q$3004,ENSAYOS!$C$5:$C$3004,F9,ENSAYOS!$Q$5:$Q$3004,">0")) -> 98.991237 | S9: =IF(N(M9)<2,"",SQRT(MAX(0,(SUMIFS(ENSAYOS!$X$5:$X$3004,ENSAYOS!$C$5:$C$3004,F9,ENSAYOS!$Q$5:$Q$3004,">0")-M9*P9^2)/(M9-1)))) -> 11.44389 | T9: =IF(S9="","",S9/P9) -> 0.13457628 | U9: =IF(N(M9)=0,"",IF(N9>=CONFIG!$B$27,"",AVERAGEIFS(ENSAYOS!$Q$5:$Q$3004,ENSAYOS!$C$5:$C$3004,F9,ENSAYOS!$Q$5:$Q$3004,">0",ENSAYOS!$G$5:$G$3004,N9))) | V9: =IF(N(M9)=0,"",IF(COUNTIFS(ENSAYOS!$C$5:$C$3004,F9,ENSAYOS!$Q$5:$Q$3004,">0",ENSAYOS!$G$5:$G$3004,">="&CONFIG!$B$27)=0,"",AVERAGEIFS(ENSAYOS!$Q$5:$Q$3004,ENSAYOS!$C$5:$C$3004,F9,ENSAYOS!$Q$5:$Q$3004,">0",ENSAYOS!$G$5:$G$3004,">="&CONFIG!$B$27))) -> 85.03646 | W9: =IF(AND(U9<>"",V9<>""),U9/V9,"") | X9: =IF(U9="","",INDEX('CURVA EDAD'!$E$5:$E$32,MIN(28,MAX(1,N9)))) | Y9: =IF(V9<>"",V9,IF(U9="","",U9/X9)) -> 85.03646 | Z9: =IF(V9<>"",_xlfn.MINIFS(ENSAYOS!$Q$5:$Q$3004,ENSAYOS!$C$5:$C$3004,F9,ENSAYOS!$Q$5:$Q$3004,">0",ENSAYOS!$G$5:$G$3004,">="&CONFIG!$B$27),IF(U9="","",_xlfn.MINIFS(ENSAYOS!$Q$5:$Q$3004,ENSAYOS!$C$5:$C$3004,F9,ENSAYOS!$Q$5:$Q$3004,">0",ENSAYOS!$G$5:$G$3004,N9)/X9)) -> 65.908471 | AA9: =IF(D9="","",IFERROR(1/(1/INDEX(CONFIG!$J$5:$J$14,MATCH(D9,CONFIG!$D$5:$D$14,0))),"")) | AB9: =IF(D9="","",IFERROR(1/(1/INDEX(CONFIG!$K$5:$K$14,MATCH(D9,CONFIG!$D$5:$D$14,0))),"")) | AC9: =IF(N(M9)=0,"",IF(AA9="","Sin spec",IF(AND(Y9>=AA9,OR(AB9="",Z9>=AB9)),"CUMPLE","NO CUMPLE")&IF(V9=""," (est.)",""))) -> Sin spec | AD9: =IF(F9="","",IF(COUNTIFS(ABSORCION!$C$5:$C$1004,F9,ABSORCION!$I$5:$I$1004,">0")=0,"",AVERAGEIFS(ABSORCION!$I$5:$I$1004,ABSORCION!$C$5:$C$1004,F9,ABSORCION!$I$5:$I$1004,">0"))) | AE9: =IF(F9="","",IF(COUNTIFS(ABSORCION!$C$5:$C$1004,F9,ABSORCION!$I$5:$I$1004,">0")=0,"",AVERAGEIFS(ABSORCION!$K$5:$K$1004,ABSORCION!$C$5:$C$1004,F9,ABSORCION!$I$5:$I$1004,">0"))) | AF9: =IF(AE9="","",IF(AE9>=CONFIG!$E$21,CONFIG!$F$21,IF(AE9>=CONFIG!$E$20,CONFIG!$F$20,CONFIG!$F$19))) | AG9: =IF(F9="","",TRIM(IF(N(M9)=0,"Sin ensayos. ","")&IF(AND(N(M9)>0,N(M9)<CONFIG!$B$26),"Menos de "&CONFIG!$B$26&" probetas. ","")&IF(N(T9)>CONFIG!$B$25,"CV alto. ","")&IF(AND(N(AD9)>0,N(AD9)>N(AF9)),"Absorción alta. ",""))) | AH9: =IF(AND(N(M9)>0,OR(CONTROL!$C$4="TODAS",C9=CONTROL!$C$4),D9=CONTROL!$C$5),MAX($AH$4:AH8)+1,"") -> 4 | AI9: =IF(AH9="","",P9^2) -> 7231.1995
A10: =IF(B10="","",ROW()-4) -> 6 | B10: 45646 | C10: P2 | D10: Block 8" | F10: =IF(OR(B10="",C10="",D10=""),"",IFERROR(INDEX(CONFIG!$E$5:$E$14,MATCH(D10,CONFIG!$D$5:$D$14,0)),"?")&RIGHT("0"&DAY(B10),2)&RIGHT("0"&MONTH(B10),2)&RIGHT(YEAR(B10),2)&C10&IF(E10="","","-"&E10)) -> 8201224P2 | G10: P28201224 | M10: =IF(F10="","",COUNTIFS(ENSAYOS!$C$5:$C$3004,F10,ENSAYOS!$Q$5:$Q$3004,">0")) -> 9 | N10: =IF(N(M10)=0,"",_xlfn.MINIFS(ENSAYOS!$G$5:$G$3004,ENSAYOS!$C$5:$C$3004,F10,ENSAYOS!$Q$5:$Q$3004,">0")) -> 26 | O10: =IF(N(M10)=0,"",_xlfn.MAXIFS(ENSAYOS!$G$5:$G$3004,ENSAYOS!$C$5:$C$3004,F10,ENSAYOS!$Q$5:$Q$3004,">0")) -> 26 | P10: =IF(N(M10)=0,"",AVERAGEIFS(ENSAYOS!$Q$5:$Q$3004,ENSAYOS!$C$5:$C$3004,F10,ENSAYOS!$Q$5:$Q$3004,">0")) -> 104.07653 | Q10: =IF(N(M10)=0,"",_xlfn.MINIFS(ENSAYOS!$Q$5:$Q$3004,ENSAYOS!$C$5:$C$3004,F10,ENSAYOS!$Q$5:$Q$3004,">0")) -> 56.715352 | R10: =IF(N(M10)=0,"",_xlfn.MAXIFS(ENSAYOS!$Q$5:$Q$3004,ENSAYOS!$C$5:$C$3004,F10,ENSAYOS!$Q$5:$Q$3004,">0")) -> 127.38542 | S10: =IF(N(M10)<2,"",SQRT(MAX(0,(SUMIFS(ENSAYOS!$X$5:$X$3004,ENSAYOS!$C$5:$C$3004,F10,ENSAYOS!$Q$5:$Q$3004,">0")-M10*P10^2)/(M10-1)))) -> 24.394648 | T10: =IF(S10="","",S10/P10) -> 0.23439145 | U10: =IF(N(M10)=0,"",IF(N10>=CONFIG!$B$27,"",AVERAGEIFS(ENSAYOS!$Q$5:$Q$3004,ENSAYOS!$C$5:$C$3004,F10,ENSAYOS!$Q$5:$Q$3004,">0",ENSAYOS!$G$5:$G$3004,N10))) | V10: =IF(N(M10)=0,"",IF(COUNTIFS(ENSAYOS!$C$5:$C$3004,F10,ENSAYOS!$Q$5:$Q$3004,">0",ENSAYOS!$G$5:$G$3004,">="&CONFIG!$B$27)=0,"",AVERAGEIFS(ENSAYOS!$Q$5:$Q$3004,ENSAYOS!$C$5:$C$3004,F10,ENSAYOS!$Q$5:$Q$3004,">0",ENSAYOS!$G$5:$G$3004,">="&CONFIG!$B$27))) -> 104.07653 | W10: =IF(AND(U10<>"",V10<>""),U10/V10,"") | X10: =IF(U10="","",INDEX('CURVA EDAD'!$E$5:$E$32,MIN(28,MAX(1,N10)))) | Y10: =IF(V10<>"",V10,IF(U10="","",U10/X10)) -> 104.07653 | Z10: =IF(V10<>"",_xlfn.MINIFS(ENSAYOS!$Q$5:$Q$3004,ENSAYOS!$C$5:$C$3004,F10,ENSAYOS!$Q$5:$Q$3004,">0",ENSAYOS!$G$5:$G$3004,">="&CONFIG!$B$27),IF(U10="","",_xlfn.MINIFS(ENSAYOS!$Q$5:$Q$3004,ENSAYOS!$C$5:$C$3004,F10,ENSAYOS!$Q$5:$Q$3004,">0",ENSAYOS!$G$5:$G$3004,N10)/X10)) -> 56.715352 | AA10: =IF(D10="","",IFERROR(1/(1/INDEX(CONFIG!$J$5:$J$14,MATCH(D10,CONFIG!$D$5:$D$14,0))),"")) | AB10: =IF(D10="","",IFERROR(1/(1/INDEX(CONFIG!$K$5:$K$14,MATCH(D10,CONFIG!$D$5:$D$14,0))),"")) | AC10: =IF(N(M10)=0,"",IF(AA10="","Sin spec",IF(AND(Y10>=AA10,OR(AB10="",Z10>=AB10)),"CUMPLE","NO CUMPLE")&IF(V10=""," (est.)",""))) -> Sin spec | AD10: =IF(F10="","",IF(COUNTIFS(ABSORCION!$C$5:$C$1004,F10,ABSORCION!$I$5:$I$1004,">0")=0,"",AVERAGEIFS(ABSORCION!$I$5:$I$1004,ABSORCION!$C$5:$C$1004,F10,ABSORCION!$I$5:$I$1004,">0"))) | AE10: =IF(F10="","",IF(COUNTIFS(ABSORCION!$C$5:$C$1004,F10,ABSORCION!$I$5:$I$1004,">0")=0,"",AVERAGEIFS(ABSORCION!$K$5:$K$1004,ABSORCION!$C$5:$C$1004,F10,ABSORCION!$I$5:$I$1004,">0"))) | AF10: =IF(AE10="","",IF(AE10>=CONFIG!$E$21,CONFIG!$F$21,IF(AE10>=CONFIG!$E$20,CONFIG!$F$20,CONFIG!$F$19))) | AG10: =IF(F10="","",TRIM(IF(N(M10)=0,"Sin ensayos. ","")&IF(AND(N(M10)>0,N(M10)<CONFIG!$B$26),"Menos de "&CONFIG!$B$26&" probetas. ","")&IF(N(T10)>CONFIG!$B$25,"CV alto. ","")&IF(AND(N(AD10)>0,N(AD10)>N(AF10)),"Absorción alta. ",""))) -> CV alto. | AH10: =IF(AND(N(M10)>0,OR(CONTROL!$C$4="TODAS",C10=CONTROL!$C$4),D10=CONTROL!$C$5),MAX($AH$4:AH9)+1,"") -> 5 | AI10: =IF(AH10="","",P10^2) -> 10831.924
A11: =IF(B11="","",ROW()-4) -> 7 | B11: 45649 | C11: P1 | D11: Block 8" | F11: =IF(OR(B11="",C11="",D11=""),"",IFERROR(INDEX(CONFIG!$E$5:$E$14,MATCH(D11,CONFIG!$D$5:$D$14,0)),"?")&RIGHT("0"&DAY(B11),2)&RIGHT("0"&MONTH(B11),2)&RIGHT(YEAR(B11),2)&C11&IF(E11="","","-"&E11)) -> 8231224P1 | G11: 231224P1 | M11: =IF(F11="","",COUNTIFS(ENSAYOS!$C$5:$C$3004,F11,ENSAYOS!$Q$5:$Q$3004,">0")) -> 8 | N11: =IF(N(M11)=0,"",_xlfn.MINIFS(ENSAYOS!$G$5:$G$3004,ENSAYOS!$C$5:$C$3004,F11,ENSAYOS!$Q$5:$Q$3004,">0")) -> 38 | O11: =IF(N(M11)=0,"",_xlfn.MAXIFS(ENSAYOS!$G$5:$G$3004,ENSAYOS!$C$5:$C$3004,F11,ENSAYOS!$Q$5:$Q$3004,">0")) -> 39 | P11: =IF(N(M11)=0,"",AVERAGEIFS(ENSAYOS!$Q$5:$Q$3004,ENSAYOS!$C$5:$C$3004,F11,ENSAYOS!$Q$5:$Q$3004,">0")) -> 80.421941 | Q11: =IF(N(M11)=0,"",_xlfn.MINIFS(ENSAYOS!$Q$5:$Q$3004,ENSAYOS!$C$5:$C$3004,F11,ENSAYOS!$Q$5:$Q$3004,">0")) -> 60.372606 | R11: =IF(N(M11)=0,"",_xlfn.MAXIFS(ENSAYOS!$Q$5:$Q$3004,ENSAYOS!$C$5:$C$3004,F11,ENSAYOS!$Q$5:$Q$3004,">0")) -> 102.10711 | S11: =IF(N(M11)<2,"",SQRT(MAX(0,(SUMIFS(ENSAYOS!$X$5:$X$3004,ENSAYOS!$C$5:$C$3004,F11,ENSAYOS!$Q$5:$Q$3004,">0")-M11*P11^2)/(M11-1)))) -> 12.261866 | T11: =IF(S11="","",S11/P11) -> 0.15246917 | U11: =IF(N(M11)=0,"",IF(N11>=CONFIG!$B$27,"",AVERAGEIFS(ENSAYOS!$Q$5:$Q$3004,ENSAYOS!$C$5:$C$3004,F11,ENSAYOS!$Q$5:$Q$3004,">0",ENSAYOS!$G$5:$G$3004,N11))) | V11: =IF(N(M11)=0,"",IF(COUNTIFS(ENSAYOS!$C$5:$C$3004,F11,ENSAYOS!$Q$5:$Q$3004,">0",ENSAYOS!$G$5:$G$3004,">="&CONFIG!$B$27)=0,"",AVERAGEIFS(ENSAYOS!$Q$5:$Q$3004,ENSAYOS!$C$5:$C$3004,F11,ENSAYOS!$Q$5:$Q$3004,">0",ENSAYOS!$G$5:$G$3004,">="&CONFIG!$B$27))) -> 80.421941 | W11: =IF(AND(U11<>"",V11<>""),U11/V11,"") | X11: =IF(U11="","",INDEX('CURVA EDAD'!$E$5:$E$32,MIN(28,MAX(1,N11)))) | Y11: =IF(V11<>"",V11,IF(U11="","",U11/X11)) -> 80.421941 | Z11: =IF(V11<>"",_xlfn.MINIFS(ENSAYOS!$Q$5:$Q$3004,ENSAYOS!$C$5:$C$3004,F11,ENSAYOS!$Q$5:$Q$3004,">0",ENSAYOS!$G$5:$G$3004,">="&CONFIG!$B$27),IF(U11="","",_xlfn.MINIFS(ENSAYOS!$Q$5:$Q$3004,ENSAYOS!$C$5:$C$3004,F11,ENSAYOS!$Q$5:$Q$3004,">0",ENSAYOS!$G$5:$G$3004,N11)/X11)) -> 60.372606 | AA11: =IF(D11="","",IFERROR(1/(1/INDEX(CONFIG!$J$5:$J$14,MATCH(D11,CONFIG!$D$5:$D$14,0))),"")) | AB11: =IF(D11="","",IFERROR(1/(1/INDEX(CONFIG!$K$5:$K$14,MATCH(D11,CONFIG!$D$5:$D$14,0))),"")) | AC11: =IF(N(M11)=0,"",IF(AA11="","Sin spec",IF(AND(Y11>=AA11,OR(AB11="",Z11>=AB11)),"CUMPLE","NO CUMPLE")&IF(V11=""," (est.)",""))) -> Sin spec | AD11: =IF(F11="","",IF(COUNTIFS(ABSORCION!$C$5:$C$1004,F11,ABSORCION!$I$5:$I$1004,">0")=0,"",AVERAGEIFS(ABSORCION!$I$5:$I$1004,ABSORCION!$C$5:$C$1004,F11,ABSORCION!$I$5:$I$1004,">0"))) | AE11: =IF(F11="","",IF(COUNTIFS(ABSORCION!$C$5:$C$1004,F11,ABSORCION!$I$5:$I$1004,">0")=0,"",AVERAGEIFS(ABSORCION!$K$5:$K$1004,ABSORCION!$C$5:$C$1004,F11,ABSORCION!$I$5:$I$1004,">0"))) | AF11: =IF(AE11="","",IF(AE11>=CONFIG!$E$21,CONFIG!$F$21,IF(AE11>=CONFIG!$E$20,CONFIG!$F$20,CONFIG!$F$19))) | AG11: =IF(F11="","",TRIM(IF(N(M11)=0,"Sin ensayos. ","")&IF(AND(N(M11)>0,N(M11)<CONFIG!$B$26),"Menos de "&CONFIG!$B$26&" probetas. ","")&IF(N(T11)>CONFIG!$B$25,"CV alto. ","")&IF(AND(N(AD11)>0,N(AD11)>N(AF11)),"Absorción alta. ",""))) -> CV alto. | AH11: =IF(AND(N(M11)>0,OR(CONTROL!$C$4="TODAS",C11=CONTROL!$C$4),D11=CONTROL!$C$5),MAX($AH$4:AH10)+1,"") -> 6 | AI11: =IF(AH11="","",P11^2) -> 6467.6886
A12: =IF(B12="","",ROW()-4) -> 8 | B12: 45671 | C12: P1 | D12: Block 8" | F12: =IF(OR(B12="",C12="",D12=""),"",IFERROR(INDEX(CONFIG!$E$5:$E$14,MATCH(D12,CONFIG!$D$5:$D$14,0)),"?")&RIGHT("0"&DAY(B12),2)&RIGHT("0"&MONTH(B12),2)&RIGHT(YEAR(B12),2)&C12&IF(E12="","","-"&E12)) -> 8140125P1 | G12: 140125P1 | M12: =IF(F12="","",COUNTIFS(ENSAYOS!$C$5:$C$3004,F12,ENSAYOS!$Q$5:$Q$3004,">0")) -> 5 | N12: =IF(N(M12)=0,"",_xlfn.MINIFS(ENSAYOS!$G$5:$G$3004,ENSAYOS!$C$5:$C$3004,F12,ENSAYOS!$Q$5:$Q$3004,">0")) -> 4 | O12: =IF(N(M12)=0,"",_xlfn.MAXIFS(ENSAYOS!$G$5:$G$3004,ENSAYOS!$C$5:$C$3004,F12,ENSAYOS!$Q$5:$Q$3004,">0")) -> 4 | P12: =IF(N(M12)=0,"",AVERAGEIFS(ENSAYOS!$Q$5:$Q$3004,ENSAYOS!$C$5:$C$3004,F12,ENSAYOS!$Q$5:$Q$3004,">0")) -> 89.905158 | Q12: =IF(N(M12)=0,"",_xlfn.MINIFS(ENSAYOS!$Q$5:$Q$3004,ENSAYOS!$C$5:$C$3004,F12,ENSAYOS!$Q$5:$Q$3004,">0")) -> 78.451152 | R12: =IF(N(M12)=0,"",_xlfn.MAXIFS(ENSAYOS!$Q$5:$Q$3004,ENSAYOS!$C$5:$C$3004,F12,ENSAYOS!$Q$5:$Q$3004,">0")) -> 102.73069 | S12: =IF(N(M12)<2,"",SQRT(MAX(0,(SUMIFS(ENSAYOS!$X$5:$X$3004,ENSAYOS!$C$5:$C$3004,F12,ENSAYOS!$Q$5:$Q$3004,">0")-M12*P12^2)/(M12-1)))) -> 9.8066016 | T12: =IF(S12="","",S12/P12) -> 0.10907718 | U12: =IF(N(M12)=0,"",IF(N12>=CONFIG!$B$27,"",AVERAGEIFS(ENSAYOS!$Q$5:$Q$3004,ENSAYOS!$C$5:$C$3004,F12,ENSAYOS!$Q$5:$Q$3004,">0",ENSAYOS!$G$5:$G$3004,N12))) -> 89.905158 | V12: =IF(N(M12)=0,"",IF(COUNTIFS(ENSAYOS!$C$5:$C$3004,F12,ENSAYOS!$Q$5:$Q$3004,">0",ENSAYOS!$G$5:$G$3004,">="&CONFIG!$B$27)=0,"",AVERAGEIFS(ENSAYOS!$Q$5:$Q$3004,ENSAYOS!$C$5:$C$3004,F12,ENSAYOS!$Q$5:$Q$3004,">0",ENSAYOS!$G$5:$G$3004,">="&CONFIG!$B$27))) | W12: =IF(AND(U12<>"",V12<>""),U12/V12,"") | X12: =IF(U12="","",INDEX('CURVA EDAD'!$E$5:$E$32,MIN(28,MAX(1,N12)))) -> 0.87 | Y12: =IF(V12<>"",V12,IF(U12="","",U12/X12)) -> 103.33926 | Z12: =IF(V12<>"",_xlfn.MINIFS(ENSAYOS!$Q$5:$Q$3004,ENSAYOS!$C$5:$C$3004,F12,ENSAYOS!$Q$5:$Q$3004,">0",ENSAYOS!$G$5:$G$3004,">="&CONFIG!$B$27),IF(U12="","",_xlfn.MINIFS(ENSAYOS!$Q$5:$Q$3004,ENSAYOS!$C$5:$C$3004,F12,ENSAYOS!$Q$5:$Q$3004,">0",ENSAYOS!$G$5:$G$3004,N12)/X12)) -> 90.173738 | AA12: =IF(D12="","",IFERROR(1/(1/INDEX(CONFIG!$J$5:$J$14,MATCH(D12,CONFIG!$D$5:$D$14,0))),"")) | AB12: =IF(D12="","",IFERROR(1/(1/INDEX(CONFIG!$K$5:$K$14,MATCH(D12,CONFIG!$D$5:$D$14,0))),"")) | AC12: =IF(N(M12)=0,"",IF(AA12="","Sin spec",IF(AND(Y12>=AA12,OR(AB12="",Z12>=AB12)),"CUMPLE","NO CUMPLE")&IF(V12=""," (est.)",""))) -> Sin spec | AD12: =IF(F12="","",IF(COUNTIFS(ABSORCION!$C$5:$C$1004,F12,ABSORCION!$I$5:$I$1004,">0")=0,"",AVERAGEIFS(ABSORCION!$I$5:$I$1004,ABSORCION!$C$5:$C$1004,F12,ABSORCION!$I$5:$I$1004,">0"))) | AE12: =IF(F12="","",IF(COUNTIFS(ABSORCION!$C$5:$C$1004,F12,ABSORCION!$I$5:$I$1004,">0")=0,"",AVERAGEIFS(ABSORCION!$K$5:$K$1004,ABSORCION!$C$5:$C$1004,F12,ABSORCION!$I$5:$I$1004,">0"))) | AF12: =IF(AE12="","",IF(AE12>=CONFIG!$E$21,CONFIG!$F$21,IF(AE12>=CONFIG!$E$20,CONFIG!$F$20,CONFIG!$F$19))) | AG12: =IF(F12="","",TRIM(IF(N(M12)=0,"Sin ensayos. ","")&IF(AND(N(M12)>0,N(M12)<CONFIG!$B$26),"Menos de "&CONFIG!$B$26&" probetas. ","")&IF(N(T12)>CONFIG!$B$25,"CV alto. ","")&IF(AND(N(AD12)>0,N(AD12)>N(AF12)),"Absorción alta. ",""))) | AH12: =IF(AND(N(M12)>0,OR(CONTROL!$C$4="TODAS",C12=CONTROL!$C$4),D12=CONTROL!$C$5),MAX($AH$4:AH11)+1,"") -> 7 | AI12: =IF(AH12="","",P12^2) -> 8082.9375
A13: =IF(B13="","",ROW()-4) -> 9 | B13: 45674 | C13: P1 | D13: Block 8" | F13: =IF(OR(B13="",C13="",D13=""),"",IFERROR(INDEX(CONFIG!$E$5:$E$14,MATCH(D13,CONFIG!$D$5:$D$14,0)),"?")&RIGHT("0"&DAY(B13),2)&RIGHT("0"&MONTH(B13),2)&RIGHT(YEAR(B13),2)&C13&IF(E13="","","-"&E13)) -> 8170125P1 | G13: 170125P1 | M13: =IF(F13="","",COUNTIFS(ENSAYOS!$C$5:$C$3004,F13,ENSAYOS!$Q$5:$Q$3004,">0")) -> 5 | N13: =IF(N(M13)=0,"",_xlfn.MINIFS(ENSAYOS!$G$5:$G$3004,ENSAYOS!$C$5:$C$3004,F13,ENSAYOS!$Q$5:$Q$3004,">0")) -> 5 | O13: =IF(N(M13)=0,"",_xlfn.MAXIFS(ENSAYOS!$G$5:$G$3004,ENSAYOS!$C$5:$C$3004,F13,ENSAYOS!$Q$5:$Q$3004,">0")) -> 5 | P13: =IF(N(M13)=0,"",AVERAGEIFS(ENSAYOS!$Q$5:$Q$3004,ENSAYOS!$C$5:$C$3004,F13,ENSAYOS!$Q$5:$Q$3004,">0")) -> 98.516756 | Q13: =IF(N(M13)=0,"",_xlfn.MINIFS(ENSAYOS!$Q$5:$Q$3004,ENSAYOS!$C$5:$C$3004,F13,ENSAYOS!$Q$5:$Q$3004,">0")) -> 79.64557 | R13: =IF(N(M13)=0,"",_xlfn.MAXIFS(ENSAYOS!$Q$5:$Q$3004,ENSAYOS!$C$5:$C$3004,F13,ENSAYOS!$Q$5:$Q$3004,">0")) -> 114.41292 | S13: =IF(N(M13)<2,"",SQRT(MAX(0,(SUMIFS(ENSAYOS!$X$5:$X$3004,ENSAYOS!$C$5:$C$3004,F13,ENSAYOS!$Q$5:$Q$3004,">0")-M13*P13^2)/(M13-1)))) -> 15.125101 | T13: =IF(S13="","",S13/P13) -> 0.15352821 | U13: =IF(N(M13)=0,"",IF(N13>=CONFIG!$B$27,"",AVERAGEIFS(ENSAYOS!$Q$5:$Q$3004,ENSAYOS!$C$5:$C$3004,F13,ENSAYOS!$Q$5:$Q$3004,">0",ENSAYOS!$G$5:$G$3004,N13))) -> 98.516756 | V13: =IF(N(M13)=0,"",IF(COUNTIFS(ENSAYOS!$C$5:$C$3004,F13,ENSAYOS!$Q$5:$Q$3004,">0",ENSAYOS!$G$5:$G$3004,">="&CONFIG!$B$27)=0,"",AVERAGEIFS(ENSAYOS!$Q$5:$Q$3004,ENSAYOS!$C$5:$C$3004,F13,ENSAYOS!$Q$5:$Q$3004,">0",ENSAYOS!$G$5:$G$3004,">="&CONFIG!$B$27))) | W13: =IF(AND(U13<>"",V13<>""),U13/V13,"") | X13: =IF(U13="","",INDEX('CURVA EDAD'!$E$5:$E$32,MIN(28,MAX(1,N13)))) -> 0.89 | Y13: =IF(V13<>"",V13,IF(U13="","",U13/X13)) -> 110.69298 | Z13: =IF(V13<>"",_xlfn.MINIFS(ENSAYOS!$Q$5:$Q$3004,ENSAYOS!$C$5:$C$3004,F13,ENSAYOS!$Q$5:$Q$3004,">0",ENSAYOS!$G$5:$G$3004,">="&CONFIG!$B$27),IF(U13="","",_xlfn.MINIFS(ENSAYOS!$Q$5:$Q$3004,ENSAYOS!$C$5:$C$3004,F13,ENSAYOS!$Q$5:$Q$3004,">0",ENSAYOS!$G$5:$G$3004,N13)/X13)) -> 89.489404 | AA13: =IF(D13="","",IFERROR(1/(1/INDEX(CONFIG!$J$5:$J$14,MATCH(D13,CONFIG!$D$5:$D$14,0))),"")) | AB13: =IF(D13="","",IFERROR(1/(1/INDEX(CONFIG!$K$5:$K$14,MATCH(D13,CONFIG!$D$5:$D$14,0))),"")) | AC13: =IF(N(M13)=0,"",IF(AA13="","Sin spec",IF(AND(Y13>=AA13,OR(AB13="",Z13>=AB13)),"CUMPLE","NO CUMPLE")&IF(V13=""," (est.)",""))) -> Sin spec | AD13: =IF(F13="","",IF(COUNTIFS(ABSORCION!$C$5:$C$1004,F13,ABSORCION!$I$5:$I$1004,">0")=0,"",AVERAGEIFS(ABSORCION!$I$5:$I$1004,ABSORCION!$C$5:$C$1004,F13,ABSORCION!$I$5:$I$1004,">0"))) | AE13: =IF(F13="","",IF(COUNTIFS(ABSORCION!$C$5:$C$1004,F13,ABSORCION!$I$5:$I$1004,">0")=0,"",AVERAGEIFS(ABSORCION!$K$5:$K$1004,ABSORCION!$C$5:$C$1004,F13,ABSORCION!$I$5:$I$1004,">0"))) | AF13: =IF(AE13="","",IF(AE13>=CONFIG!$E$21,CONFIG!$F$21,IF(AE13>=CONFIG!$E$20,CONFIG!$F$20,CONFIG!$F$19))) | AG13: =IF(F13="","",TRIM(IF(N(M13)=0,"Sin ensayos. ","")&IF(AND(N(M13)>0,N(M13)<CONFIG!$B$26),"Menos de "&CONFIG!$B$26&" probetas. ","")&IF(N(T13)>CONFIG!$B$25,"CV alto. ","")&IF(AND(N(AD13)>0,N(AD13)>N(AF13)),"Absorción alta. ",""))) -> CV alto. | AH13: =IF(AND(N(M13)>0,OR(CONTROL!$C$4="TODAS",C13=CONTROL!$C$4),D13=CONTROL!$C$5),MAX($AH$4:AH12)+1,"") -> 8 | AI13: =IF(AH13="","",P13^2) -> 9705.5511
A14: =IF(B14="","",ROW()-4) -> 10 | B14: 45691 | C14: P2 | D14: Block 6" | F14: =IF(OR(B14="",C14="",D14=""),"",IFERROR(INDEX(CONFIG!$E$5:$E$14,MATCH(D14,CONFIG!$D$5:$D$14,0)),"?")&RIGHT("0"&DAY(B14),2)&RIGHT("0"&MONTH(B14),2)&RIGHT(YEAR(B14),2)&C14&IF(E14="","","-"&E14)) -> 6030225P2 | G14: 030225P2 | M14: =IF(F14="","",COUNTIFS(ENSAYOS!$C$5:$C$3004,F14,ENSAYOS!$Q$5:$Q$3004,">0")) -> 7 | N14: =IF(N(M14)=0,"",_xlfn.MINIFS(ENSAYOS!$G$5:$G$3004,ENSAYOS!$C$5:$C$3004,F14,ENSAYOS!$Q$5:$Q$3004,">0")) -> 3 | O14: =IF(N(M14)=0,"",_xlfn.MAXIFS(ENSAYOS!$G$5:$G$3004,ENSAYOS!$C$5:$C$3004,F14,ENSAYOS!$Q$5:$Q$3004,">0")) -> 3 | P14: =IF(N(M14)=0,"",AVERAGEIFS(ENSAYOS!$Q$5:$Q$3004,ENSAYOS!$C$5:$C$3004,F14,ENSAYOS!$Q$5:$Q$3004,">0")) -> 65.758683 | Q14: =IF(N(M14)=0,"",_xlfn.MINIFS(ENSAYOS!$Q$5:$Q$3004,ENSAYOS!$C$5:$C$3004,F14,ENSAYOS!$Q$5:$Q$3004,">0")) -> 52.054125 | R14: =IF(N(M14)=0,"",_xlfn.MAXIFS(ENSAYOS!$Q$5:$Q$3004,ENSAYOS!$C$5:$C$3004,F14,ENSAYOS!$Q$5:$Q$3004,">0")) -> 80.185072 | S14: =IF(N(M14)<2,"",SQRT(MAX(0,(SUMIFS(ENSAYOS!$X$5:$X$3004,ENSAYOS!$C$5:$C$3004,F14,ENSAYOS!$Q$5:$Q$3004,">0")-M14*P14^2)/(M14-1)))) -> 10.936682 | T14: =IF(S14="","",S14/P14) -> 0.16631541 | U14: =IF(N(M14)=0,"",IF(N14>=CONFIG!$B$27,"",AVERAGEIFS(ENSAYOS!$Q$5:$Q$3004,ENSAYOS!$C$5:$C$3004,F14,ENSAYOS!$Q$5:$Q$3004,">0",ENSAYOS!$G$5:$G$3004,N14))) -> 65.758683 | V14: =IF(N(M14)=0,"",IF(COUNTIFS(ENSAYOS!$C$5:$C$3004,F14,ENSAYOS!$Q$5:$Q$3004,">0",ENSAYOS!$G$5:$G$3004,">="&CONFIG!$B$27)=0,"",AVERAGEIFS(ENSAYOS!$Q$5:$Q$3004,ENSAYOS!$C$5:$C$3004,F14,ENSAYOS!$Q$5:$Q$3004,">0",ENSAYOS!$G$5:$G$3004,">="&CONFIG!$B$27))) | W14: =IF(AND(U14<>"",V14<>""),U14/V14,"") | X14: =IF(U14="","",INDEX('CURVA EDAD'!$E$5:$E$32,MIN(28,MAX(1,N14)))) -> 0.84 | Y14: =IF(V14<>"",V14,IF(U14="","",U14/X14)) -> 78.284146 | Z14: =IF(V14<>"",_xlfn.MINIFS(ENSAYOS!$Q$5:$Q$3004,ENSAYOS!$C$5:$C$3004,F14,ENSAYOS!$Q$5:$Q$3004,">0",ENSAYOS!$G$5:$G$3004,">="&CONFIG!$B$27),IF(U14="","",_xlfn.MINIFS(ENSAYOS!$Q$5:$Q$3004,ENSAYOS!$C$5:$C$3004,F14,ENSAYOS!$Q$5:$Q$3004,">0",ENSAYOS!$G$5:$G$3004,N14)/X14)) -> 61.969196 | AA14: =IF(D14="","",IFERROR(1/(1/INDEX(CONFIG!$J$5:$J$14,MATCH(D14,CONFIG!$D$5:$D$14,0))),"")) | AB14: =IF(D14="","",IFERROR(1/(1/INDEX(CONFIG!$K$5:$K$14,MATCH(D14,CONFIG!$D$5:$D$14,0))),"")) | AC14: =IF(N(M14)=0,"",IF(AA14="","Sin spec",IF(AND(Y14>=AA14,OR(AB14="",Z14>=AB14)),"CUMPLE","NO CUMPLE")&IF(V14=""," (est.)",""))) -> Sin spec | AD14: =IF(F14="","",IF(COUNTIFS(ABSORCION!$C$5:$C$1004,F14,ABSORCION!$I$5:$I$1004,">0")=0,"",AVERAGEIFS(ABSORCION!$I$5:$I$1004,ABSORCION!$C$5:$C$1004,F14,ABSORCION!$I$5:$I$1004,">0"))) | AE14: =IF(F14="","",IF(COUNTIFS(ABSORCION!$C$5:$C$1004,F14,ABSORCION!$I$5:$I$1004,">0")=0,"",AVERAGEIFS(ABSORCION!$K$5:$K$1004,ABSORCION!$C$5:$C$1004,F14,ABSORCION!$I$5:$I$1004,">0"))) | AF14: =IF(AE14="","",IF(AE14>=CONFIG!$E$21,CONFIG!$F$21,IF(AE14>=CONFIG!$E$20,CONFIG!$F$20,CONFIG!$F$19))) | AG14: =IF(F14="","",TRIM(IF(N(M14)=0,"Sin ensayos. ","")&IF(AND(N(M14)>0,N(M14)<CONFIG!$B$26),"Menos de "&CONFIG!$B$26&" probetas. ","")&IF(N(T14)>CONFIG!$B$25,"CV alto. ","")&IF(AND(N(AD14)>0,N(AD14)>N(AF14)),"Absorción alta. ",""))) -> CV alto. | AH14: =IF(AND(N(M14)>0,OR(CONTROL!$C$4="TODAS",C14=CONTROL!$C$4),D14=CONTROL!$C$5),MAX($AH$4:AH13)+1,"") | AI14: =IF(AH14="","",P14^2)
A15: =IF(B15="","",ROW()-4) -> 11 | B15: 45694 | C15: P1 | D15: Block 8" | F15: =IF(OR(B15="",C15="",D15=""),"",IFERROR(INDEX(CONFIG!$E$5:$E$14,MATCH(D15,CONFIG!$D$5:$D$14,0)),"?")&RIGHT("0"&DAY(B15),2)&RIGHT("0"&MONTH(B15),2)&RIGHT(YEAR(B15),2)&C15&IF(E15="","","-"&E15)) -> 8060225P1 | G15: 060225P1 | M15: =IF(F15="","",COUNTIFS(ENSAYOS!$C$5:$C$3004,F15,ENSAYOS!$Q$5:$Q$3004,">0")) -> 4 | N15: =IF(N(M15)=0,"",_xlfn.MINIFS(ENSAYOS!$G$5:$G$3004,ENSAYOS!$C$5:$C$3004,F15,ENSAYOS!$Q$5:$Q$3004,">0")) -> 5 | O15: =IF(N(M15)=0,"",_xlfn.MAXIFS(ENSAYOS!$G$5:$G$3004,ENSAYOS!$C$5:$C$3004,F15,ENSAYOS!$Q$5:$Q$3004,">0")) -> 5 | P15: =IF(N(M15)=0,"",AVERAGEIFS(ENSAYOS!$Q$5:$Q$3004,ENSAYOS!$C$5:$C$3004,F15,ENSAYOS!$Q$5:$Q$3004,">0")) -> 87.764362 | Q15: =IF(N(M15)=0,"",_xlfn.MINIFS(ENSAYOS!$Q$5:$Q$3004,ENSAYOS!$C$5:$C$3004,F15,ENSAYOS!$Q$5:$Q$3004,">0")) -> 82.567997 | R15: =IF(N(M15)=0,"",_xlfn.MAXIFS(ENSAYOS!$Q$5:$Q$3004,ENSAYOS!$C$5:$C$3004,F15,ENSAYOS!$Q$5:$Q$3004,">0")) -> 92.036352 | S15: =IF(N(M15)<2,"",SQRT(MAX(0,(SUMIFS(ENSAYOS!$X$5:$X$3004,ENSAYOS!$C$5:$C$3004,F15,ENSAYOS!$Q$5:$Q$3004,">0")-M15*P15^2)/(M15-1)))) -> 4.0053829 | T15: =IF(S15="","",S15/P15) -> 0.04563792 | U15: =IF(N(M15)=0,"",IF(N15>=CONFIG!$B$27,"",AVERAGEIFS(ENSAYOS!$Q$5:$Q$3004,ENSAYOS!$C$5:$C$3004,F15,ENSAYOS!$Q$5:$Q$3004,">0",ENSAYOS!$G$5:$G$3004,N15))) -> 87.764362 | V15: =IF(N(M15)=0,"",IF(COUNTIFS(ENSAYOS!$C$5:$C$3004,F15,ENSAYOS!$Q$5:$Q$3004,">0",ENSAYOS!$G$5:$G$3004,">="&CONFIG!$B$27)=0,"",AVERAGEIFS(ENSAYOS!$Q$5:$Q$3004,ENSAYOS!$C$5:$C$3004,F15,ENSAYOS!$Q$5:$Q$3004,">0",ENSAYOS!$G$5:$G$3004,">="&CONFIG!$B$27))) | W15: =IF(AND(U15<>"",V15<>""),U15/V15,"") | X15: =IF(U15="","",INDEX('CURVA EDAD'!$E$5:$E$32,MIN(28,MAX(1,N15)))) -> 0.89 | Y15: =IF(V15<>"",V15,IF(U15="","",U15/X15)) -> 98.611643 | Z15: =IF(V15<>"",_xlfn.MINIFS(ENSAYOS!$Q$5:$Q$3004,ENSAYOS!$C$5:$C$3004,F15,ENSAYOS!$Q$5:$Q$3004,">0",ENSAYOS!$G$5:$G$3004,">="&CONFIG!$B$27),IF(U15="","",_xlfn.MINIFS(ENSAYOS!$Q$5:$Q$3004,ENSAYOS!$C$5:$C$3004,F15,ENSAYOS!$Q$5:$Q$3004,">0",ENSAYOS!$G$5:$G$3004,N15)/X15)) -> 92.773031 | AA15: =IF(D15="","",IFERROR(1/(1/INDEX(CONFIG!$J$5:$J$14,MATCH(D15,CONFIG!$D$5:$D$14,0))),"")) | AB15: =IF(D15="","",IFERROR(1/(1/INDEX(CONFIG!$K$5:$K$14,MATCH(D15,CONFIG!$D$5:$D$14,0))),"")) | AC15: =IF(N(M15)=0,"",IF(AA15="","Sin spec",IF(AND(Y15>=AA15,OR(AB15="",Z15>=AB15)),"CUMPLE","NO CUMPLE")&IF(V15=""," (est.)",""))) -> Sin spec | AD15: =IF(F15="","",IF(COUNTIFS(ABSORCION!$C$5:$C$1004,F15,ABSORCION!$I$5:$I$1004,">0")=0,"",AVERAGEIFS(ABSORCION!$I$5:$I$1004,ABSORCION!$C$5:$C$1004,F15,ABSORCION!$I$5:$I$1004,">0"))) | AE15: =IF(F15="","",IF(COUNTIFS(ABSORCION!$C$5:$C$1004,F15,ABSORCION!$I$5:$I$1004,">0")=0,"",AVERAGEIFS(ABSORCION!$K$5:$K$1004,ABSORCION!$C$5:$C$1004,F15,ABSORCION!$I$5:$I$1004,">0"))) | AF15: =IF(AE15="","",IF(AE15>=CONFIG!$E$21,CONFIG!$F$21,IF(AE15>=CONFIG!$E$20,CONFIG!$F$20,CONFIG!$F$19))) | AG15: =IF(F15="","",TRIM(IF(N(M15)=0,"Sin ensayos. ","")&IF(AND(N(M15)>0,N(M15)<CONFIG!$B$26),"Menos de "&CONFIG!$B$26&" probetas. ","")&IF(N(T15)>CONFIG!$B$25,"CV alto. ","")&IF(AND(N(AD15)>0,N(AD15)>N(AF15)),"Absorción alta. ",""))) | AH15: =IF(AND(N(M15)>0,OR(CONTROL!$C$4="TODAS",C15=CONTROL!$C$4),D15=CONTROL!$C$5),MAX($AH$4:AH14)+1,"") -> 9 | AI15: =IF(AH15="","",P15^2) -> 7702.5833
A16: =IF(B16="","",ROW()-4) -> 12 | B16: 45699 | C16: P1 | D16: Block 8" | F16: =IF(OR(B16="",C16="",D16=""),"",IFERROR(INDEX(CONFIG!$E$5:$E$14,MATCH(D16,CONFIG!$D$5:$D$14,0)),"?")&RIGHT("0"&DAY(B16),2)&RIGHT("0"&MONTH(B16),2)&RIGHT(YEAR(B16),2)&C16&IF(E16="","","-"&E16)) -> 8110225P1 | M16: =IF(F16="","",COUNTIFS(ENSAYOS!$C$5:$C$3004,F16,ENSAYOS!$Q$5:$Q$3004,">0")) -> 4 | N16: =IF(N(M16)=0,"",_xlfn.MINIFS(ENSAYOS!$G$5:$G$3004,ENSAYOS!$C$5:$C$3004,F16,ENSAYOS!$Q$5:$Q$3004,">0")) -> 2 | O16: =IF(N(M16)=0,"",_xlfn.MAXIFS(ENSAYOS!$G$5:$G$3004,ENSAYOS!$C$5:$C$3004,F16,ENSAYOS!$Q$5:$Q$3004,">0")) -> 2 | P16: =IF(N(M16)=0,"",AVERAGEIFS(ENSAYOS!$Q$5:$Q$3004,ENSAYOS!$C$5:$C$3004,F16,ENSAYOS!$Q$5:$Q$3004,">0")) -> 64.297306 | Q16: =IF(N(M16)=0,"",_xlfn.MINIFS(ENSAYOS!$Q$5:$Q$3004,ENSAYOS!$C$5:$C$3004,F16,ENSAYOS!$Q$5:$Q$3004,">0")) -> 55.484583 | R16: =IF(N(M16)=0,"",_xlfn.MAXIFS(ENSAYOS!$Q$5:$Q$3004,ENSAYOS!$C$5:$C$3004,F16,ENSAYOS!$Q$5:$Q$3004,">0")) -> 72.385589 | S16: =IF(N(M16)<2,"",SQRT(MAX(0,(SUMIFS(ENSAYOS!$X$5:$X$3004,ENSAYOS!$C$5:$C$3004,F16,ENSAYOS!$Q$5:$Q$3004,">0")-M16*P16^2)/(M16-1)))) -> 7.0733406 | T16: =IF(S16="","",S16/P16) -> 0.11000991 | U16: =IF(N(M16)=0,"",IF(N16>=CONFIG!$B$27,"",AVERAGEIFS(ENSAYOS!$Q$5:$Q$3004,ENSAYOS!$C$5:$C$3004,F16,ENSAYOS!$Q$5:$Q$3004,">0",ENSAYOS!$G$5:$G$3004,N16))) -> 64.297306 | V16: =IF(N(M16)=0,"",IF(COUNTIFS(ENSAYOS!$C$5:$C$3004,F16,ENSAYOS!$Q$5:$Q$3004,">0",ENSAYOS!$G$5:$G$3004,">="&CONFIG!$B$27)=0,"",AVERAGEIFS(ENSAYOS!$Q$5:$Q$3004,ENSAYOS!$C$5:$C$3004,F16,ENSAYOS!$Q$5:$Q$3004,">0",ENSAYOS!$G$5:$G$3004,">="&CONFIG!$B$27))) | W16: =IF(AND(U16<>"",V16<>""),U16/V16,"") | X16: =IF(U16="","",INDEX('CURVA EDAD'!$E$5:$E$32,MIN(28,MAX(1,N16)))) -> 0.77 | Y16: =IF(V16<>"",V16,IF(U16="","",U16/X16)) -> 83.502995 | Z16: =IF(V16<>"",_xlfn.MINIFS(ENSAYOS!$Q$5:$Q$3004,ENSAYOS!$C$5:$C$3004,F16,ENSAYOS!$Q$5:$Q$3004,">0",ENSAYOS!$G$5:$G$3004,">="&CONFIG!$B$27),IF(U16="","",_xlfn.MINIFS(ENSAYOS!$Q$5:$Q$3004,ENSAYOS!$C$5:$C$3004,F16,ENSAYOS!$Q$5:$Q$3004,">0",ENSAYOS!$G$5:$G$3004,N16)/X16)) -> 72.0579 | AA16: =IF(D16="","",IFERROR(1/(1/INDEX(CONFIG!$J$5:$J$14,MATCH(D16,CONFIG!$D$5:$D$14,0))),"")) | AB16: =IF(D16="","",IFERROR(1/(1/INDEX(CONFIG!$K$5:$K$14,MATCH(D16,CONFIG!$D$5:$D$14,0))),"")) | AC16: =IF(N(M16)=0,"",IF(AA16="","Sin spec",IF(AND(Y16>=AA16,OR(AB16="",Z16>=AB16)),"CUMPLE","NO CUMPLE")&IF(V16=""," (est.)",""))) -> Sin spec | AD16: =IF(F16="","",IF(COUNTIFS(ABSORCION!$C$5:$C$1004,F16,ABSORCION!$I$5:$I$1004,">0")=0,"",AVERAGEIFS(ABSORCION!$I$5:$I$1004,ABSORCION!$C$5:$C$1004,F16,ABSORCION!$I$5:$I$1004,">0"))) | AE16: =IF(F16="","",IF(COUNTIFS(ABSORCION!$C$5:$C$1004,F16,ABSORCION!$I$5:$I$1004,">0")=0,"",AVERAGEIFS(ABSORCION!$K$5:$K$1004,ABSORCION!$C$5:$C$1004,F16,ABSORCION!$I$5:$I$1004,">0"))) | AF16: =IF(AE16="","",IF(AE16>=CONFIG!$E$21,CONFIG!$F$21,IF(AE16>=CONFIG!$E$20,CONFIG!$F$20,CONFIG!$F$19))) | AG16: =IF(F16="","",TRIM(IF(N(M16)=0,"Sin ensayos. ","")&IF(AND(N(M16)>0,N(M16)<CONFIG!$B$26),"Menos de "&CONFIG!$B$26&" probetas. ","")&IF(N(T16)>CONFIG!$B$25,"CV alto. ","")&IF(AND(N(AD16)>0,N(AD16)>N(AF16)),"Absorción alta. ",""))) | AH16: =IF(AND(N(M16)>0,OR(CONTROL!$C$4="TODAS",C16=CONTROL!$C$4),D16=CONTROL!$C$5),MAX($AH$4:AH15)+1,"") -> 10 | AI16: =IF(AH16="","",P16^2) -> 4134.1436
A17: =IF(B17="","",ROW()-4) -> 13 | B17: 45700 | C17: P2 | D17: Block 6" | F17: =IF(OR(B17="",C17="",D17=""),"",IFERROR(INDEX(CONFIG!$E$5:$E$14,MATCH(D17,CONFIG!$D$5:$D$14,0)),"?")&RIGHT("0"&DAY(B17),2)&RIGHT("0"&MONTH(B17),2)&RIGHT(YEAR(B17),2)&C17&IF(E17="","","-"&E17)) -> 6120225P2 | M17: =IF(F17="","",COUNTIFS(ENSAYOS!$C$5:$C$3004,F17,ENSAYOS!$Q$5:$Q$3004,">0")) -> 5 | N17: =IF(N(M17)=0,"",_xlfn.MINIFS(ENSAYOS!$G$5:$G$3004,ENSAYOS!$C$5:$C$3004,F17,ENSAYOS!$Q$5:$Q$3004,">0")) -> 5 | O17: =IF(N(M17)=0,"",_xlfn.MAXIFS(ENSAYOS!$G$5:$G$3004,ENSAYOS!$C$5:$C$3004,F17,ENSAYOS!$Q$5:$Q$3004,">0")) -> 5 | P17: =IF(N(M17)=0,"",AVERAGEIFS(ENSAYOS!$Q$5:$Q$3004,ENSAYOS!$C$5:$C$3004,F17,ENSAYOS!$Q$5:$Q$3004,">0")) -> 67.639983 | Q17: =IF(N(M17)=0,"",_xlfn.MINIFS(ENSAYOS!$Q$5:$Q$3004,ENSAYOS!$C$5:$C$3004,F17,ENSAYOS!$Q$5:$Q$3004,">0")) -> 60.750764 | R17: =IF(N(M17)=0,"",_xlfn.MAXIFS(ENSAYOS!$Q$5:$Q$3004,ENSAYOS!$C$5:$C$3004,F17,ENSAYOS!$Q$5:$Q$3004,">0")) -> 83.605412 | S17: =IF(N(M17)<2,"",SQRT(MAX(0,(SUMIFS(ENSAYOS!$X$5:$X$3004,ENSAYOS!$C$5:$C$3004,F17,ENSAYOS!$Q$5:$Q$3004,">0")-M17*P17^2)/(M17-1)))) -> 9.3749847 | T17: =IF(S17="","",S17/P17) -> 0.13860123 | U17: =IF(N(M17)=0,"",IF(N17>=CONFIG!$B$27,"",AVERAGEIFS(ENSAYOS!$Q$5:$Q$3004,ENSAYOS!$C$5:$C$3004,F17,ENSAYOS!$Q$5:$Q$3004,">0",ENSAYOS!$G$5:$G$3004,N17))) -> 67.639983 | V17: =IF(N(M17)=0,"",IF(COUNTIFS(ENSAYOS!$C$5:$C$3004,F17,ENSAYOS!$Q$5:$Q$3004,">0",ENSAYOS!$G$5:$G$3004,">="&CONFIG!$B$27)=0,"",AVERAGEIFS(ENSAYOS!$Q$5:$Q$3004,ENSAYOS!$C$5:$C$3004,F17,ENSAYOS!$Q$5:$Q$3004,">0",ENSAYOS!$G$5:$G$3004,">="&CONFIG!$B$27))) | W17: =IF(AND(U17<>"",V17<>""),U17/V17,"") | X17: =IF(U17="","",INDEX('CURVA EDAD'!$E$5:$E$32,MIN(28,MAX(1,N17)))) -> 0.89 | Y17: =IF(V17<>"",V17,IF(U17="","",U17/X17)) -> 75.99998 | Z17: =IF(V17<>"",_xlfn.MINIFS(ENSAYOS!$Q$5:$Q$3004,ENSAYOS!$C$5:$C$3004,F17,ENSAYOS!$Q$5:$Q$3004,">0",ENSAYOS!$G$5:$G$3004,">="&CONFIG!$B$27),IF(U17="","",_xlfn.MINIFS(ENSAYOS!$Q$5:$Q$3004,ENSAYOS!$C$5:$C$3004,F17,ENSAYOS!$Q$5:$Q$3004,">0",ENSAYOS!$G$5:$G$3004,N17)/X17)) -> 68.259285 | AA17: =IF(D17="","",IFERROR(1/(1/INDEX(CONFIG!$J$5:$J$14,MATCH(D17,CONFIG!$D$5:$D$14,0))),"")) | AB17: =IF(D17="","",IFERROR(1/(1/INDEX(CONFIG!$K$5:$K$14,MATCH(D17,CONFIG!$D$5:$D$14,0))),"")) | AC17: =IF(N(M17)=0,"",IF(AA17="","Sin spec",IF(AND(Y17>=AA17,OR(AB17="",Z17>=AB17)),"CUMPLE","NO CUMPLE")&IF(V17=""," (est.)",""))) -> Sin spec | AD17: =IF(F17="","",IF(COUNTIFS(ABSORCION!$C$5:$C$1004,F17,ABSORCION!$I$5:$I$1004,">0")=0,"",AVERAGEIFS(ABSORCION!$I$5:$I$1004,ABSORCION!$C$5:$C$1004,F17,ABSORCION!$I$5:$I$1004,">0"))) | AE17: =IF(F17="","",IF(COUNTIFS(ABSORCION!$C$5:$C$1004,F17,ABSORCION!$I$5:$I$1004,">0")=0,"",AVERAGEIFS(ABSORCION!$K$5:$K$1004,ABSORCION!$C$5:$C$1004,F17,ABSORCION!$I$5:$I$1004,">0"))) | AF17: =IF(AE17="","",IF(AE17>=CONFIG!$E$21,CONFIG!$F$21,IF(AE17>=CONFIG!$E$20,CONFIG!$F$20,CONFIG!$F$19))) | AG17: =IF(F17="","",TRIM(IF(N(M17)=0,"Sin ensayos. ","")&IF(AND(N(M17)>0,N(M17)<CONFIG!$B$26),"Menos de "&CONFIG!$B$26&" probetas. ","")&IF(N(T17)>CONFIG!$B$25,"CV alto. ","")&IF(AND(N(AD17)>0,N(AD17)>N(AF17)),"Absorción alta. ",""))) | AH17: =IF(AND(N(M17)>0,OR(CONTROL!$C$4="TODAS",C17=CONTROL!$C$4),D17=CONTROL!$C$5),MAX($AH$4:AH16)+1,"") | AI17: =IF(AH17="","",P17^2)
A18: =IF(B18="","",ROW()-4) -> 14 | B18: 45700 | C18: P1 | D18: Block 8" | F18: =IF(OR(B18="",C18="",D18=""),"",IFERROR(INDEX(CONFIG!$E$5:$E$14,MATCH(D18,CONFIG!$D$5:$D$14,0)),"?")&RIGHT("0"&DAY(B18),2)&RIGHT("0"&MONTH(B18),2)&RIGHT(YEAR(B18),2)&C18&IF(E18="","","-"&E18)) -> 8120225P1 | M18: =IF(F18="","",COUNTIFS(ENSAYOS!$C$5:$C$3004,F18,ENSAYOS!$Q$5:$Q$3004,">0")) -> 5 | N18: =IF(N(M18)=0,"",_xlfn.MINIFS(ENSAYOS!$G$5:$G$3004,ENSAYOS!$C$5:$C$3004,F18,ENSAYOS!$Q$5:$Q$3004,">0")) -> 5 | O18: =IF(N(M18)=0,"",_xlfn.MAXIFS(ENSAYOS!$G$5:$G$3004,ENSAYOS!$C$5:$C$3004,F18,ENSAYOS!$Q$5:$Q$3004,">0")) -> 5 | P18: =IF(N(M18)=0,"",AVERAGEIFS(ENSAYOS!$Q$5:$Q$3004,ENSAYOS!$C$5:$C$3004,F18,ENSAYOS!$Q$5:$Q$3004,">0")) -> 76.222785 | Q18: =IF(N(M18)=0,"",_xlfn.MINIFS(ENSAYOS!$Q$5:$Q$3004,ENSAYOS!$C$5:$C$3004,F18,ENSAYOS!$Q$5:$Q$3004,">0")) -> 57.533268 | R18: =IF(N(M18)=0,"",_xlfn.MAXIFS(ENSAYOS!$Q$5:$Q$3004,ENSAYOS!$C$5:$C$3004,F18,ENSAYOS!$Q$5:$Q$3004,">0")) -> 90.900357 | S18: =IF(N(M18)<2,"",SQRT(MAX(0,(SUMIFS(ENSAYOS!$X$5:$X$3004,ENSAYOS!$C$5:$C$3004,F18,ENSAYOS!$Q$5:$Q$3004,">0")-M18*P18^2)/(M18-1)))) -> 13.502216 | T18: =IF(S18="","",S18/P18) -> 0.17714147 | U18: =IF(N(M18)=0,"",IF(N18>=CONFIG!$B$27,"",AVERAGEIFS(ENSAYOS!$Q$5:$Q$3004,ENSAYOS!$C$5:$C$3004,F18,ENSAYOS!$Q$5:$Q$3004,">0",ENSAYOS!$G$5:$G$3004,N18))) -> 76.222785 | V18: =IF(N(M18)=0,"",IF(COUNTIFS(ENSAYOS!$C$5:$C$3004,F18,ENSAYOS!$Q$5:$Q$3004,">0",ENSAYOS!$G$5:$G$3004,">="&CONFIG!$B$27)=0,"",AVERAGEIFS(ENSAYOS!$Q$5:$Q$3004,ENSAYOS!$C$5:$C$3004,F18,ENSAYOS!$Q$5:$Q$3004,">0",ENSAYOS!$G$5:$G$3004,">="&CONFIG!$B$27))) | W18: =IF(AND(U18<>"",V18<>""),U18/V18,"") | X18: =IF(U18="","",INDEX('CURVA EDAD'!$E$5:$E$32,MIN(28,MAX(1,N18)))) -> 0.89 | Y18: =IF(V18<>"",V18,IF(U18="","",U18/X18)) -> 85.643578 | Z18: =IF(V18<>"",_xlfn.MINIFS(ENSAYOS!$Q$5:$Q$3004,ENSAYOS!$C$5:$C$3004,F18,ENSAYOS!$Q$5:$Q$3004,">0",ENSAYOS!$G$5:$G$3004,">="&CONFIG!$B$27),IF(U18="","",_xlfn.MINIFS(ENSAYOS!$Q$5:$Q$3004,ENSAYOS!$C$5:$C$3004,F18,ENSAYOS!$Q$5:$Q$3004,">0",ENSAYOS!$G$5:$G$3004,N18)/X18)) -> 64.644122 | AA18: =IF(D18="","",IFERROR(1/(1/INDEX(CONFIG!$J$5:$J$14,MATCH(D18,CONFIG!$D$5:$D$14,0))),"")) | AB18: =IF(D18="","",IFERROR(1/(1/INDEX(CONFIG!$K$5:$K$14,MATCH(D18,CONFIG!$D$5:$D$14,0))),"")) | AC18: =IF(N(M18)=0,"",IF(AA18="","Sin spec",IF(AND(Y18>=AA18,OR(AB18="",Z18>=AB18)),"CUMPLE","NO CUMPLE")&IF(V18=""," (est.)",""))) -> Sin spec | AD18: =IF(F18="","",IF(COUNTIFS(ABSORCION!$C$5:$C$1004,F18,ABSORCION!$I$5:$I$1004,">0")=0,"",AVERAGEIFS(ABSORCION!$I$5:$I$1004,ABSORCION!$C$5:$C$1004,F18,ABSORCION!$I$5:$I$1004,">0"))) | AE18: =IF(F18="","",IF(COUNTIFS(ABSORCION!$C$5:$C$1004,F18,ABSORCION!$I$5:$I$1004,">0")=0,"",AVERAGEIFS(ABSORCION!$K$5:$K$1004,ABSORCION!$C$5:$C$1004,F18,ABSORCION!$I$5:$I$1004,">0"))) | AF18: =IF(AE18="","",IF(AE18>=CONFIG!$E$21,CONFIG!$F$21,IF(AE18>=CONFIG!$E$20,CONFIG!$F$20,CONFIG!$F$19))) | AG18: =IF(F18="","",TRIM(IF(N(M18)=0,"Sin ensayos. ","")&IF(AND(N(M18)>0,N(M18)<CONFIG!$B$26),"Menos de "&CONFIG!$B$26&" probetas. ","")&IF(N(T18)>CONFIG!$B$25,"CV alto. ","")&IF(AND(N(AD18)>0,N(AD18)>N(AF18)),"Absorción alta. ",""))) -> CV alto. | AH18: =IF(AND(N(M18)>0,OR(CONTROL!$C$4="TODAS",C18=CONTROL!$C$4),D18=CONTROL!$C$5),MAX($AH$4:AH17)+1,"") -> 11 | AI18: =IF(AH18="","",P18^2) -> 5809.9129
A19: =IF(B19="","",ROW()-4) -> 15 | B19: 45706 | C19: P1 | D19: Block 8" | F19: =IF(OR(B19="",C19="",D19=""),"",IFERROR(INDEX(CONFIG!$E$5:$E$14,MATCH(D19,CONFIG!$D$5:$D$14,0)),"?")&RIGHT("0"&DAY(B19),2)&RIGHT("0"&MONTH(B19),2)&RIGHT(YEAR(B19),2)&C19&IF(E19="","","-"&E19)) -> 8180225P1 | M19: =IF(F19="","",COUNTIFS(ENSAYOS!$C$5:$C$3004,F19,ENSAYOS!$Q$5:$Q$3004,">0")) -> 4 | N19: =IF(N(M19)=0,"",_xlfn.MINIFS(ENSAYOS!$G$5:$G$3004,ENSAYOS!$C$5:$C$3004,F19,ENSAYOS!$Q$5:$Q$3004,">0")) -> 3 | O19: =IF(N(M19)=0,"",_xlfn.MAXIFS(ENSAYOS!$G$5:$G$3004,ENSAYOS!$C$5:$C$3004,F19,ENSAYOS!$Q$5:$Q$3004,">0")) -> 3 | P19: =IF(N(M19)=0,"",AVERAGEIFS(ENSAYOS!$Q$5:$Q$3004,ENSAYOS!$C$5:$C$3004,F19,ENSAYOS!$Q$5:$Q$3004,">0")) -> 71.263875 | Q19: =IF(N(M19)=0,"",_xlfn.MINIFS(ENSAYOS!$Q$5:$Q$3004,ENSAYOS!$C$5:$C$3004,F19,ENSAYOS!$Q$5:$Q$3004,">0")) -> 64.206426 | R19: =IF(N(M19)=0,"",_xlfn.MAXIFS(ENSAYOS!$Q$5:$Q$3004,ENSAYOS!$C$5:$C$3004,F19,ENSAYOS!$Q$5:$Q$3004,">0")) -> 76.542681 | S19: =IF(N(M19)<2,"",SQRT(MAX(0,(SUMIFS(ENSAYOS!$X$5:$X$3004,ENSAYOS!$C$5:$C$3004,F19,ENSAYOS!$Q$5:$Q$3004,">0")-M19*P19^2)/(M19-1)))) -> 5.265148 | T19: =IF(S19="","",S19/P19) -> 0.073882426 | U19: =IF(N(M19)=0,"",IF(N19>=CONFIG!$B$27,"",AVERAGEIFS(ENSAYOS!$Q$5:$Q$3004,ENSAYOS!$C$5:$C$3004,F19,ENSAYOS!$Q$5:$Q$3004,">0",ENSAYOS!$G$5:$G$3004,N19))) -> 71.263875 | V19: =IF(N(M19)=0,"",IF(COUNTIFS(ENSAYOS!$C$5:$C$3004,F19,ENSAYOS!$Q$5:$Q$3004,">0",ENSAYOS!$G$5:$G$3004,">="&CONFIG!$B$27)=0,"",AVERAGEIFS(ENSAYOS!$Q$5:$Q$3004,ENSAYOS!$C$5:$C$3004,F19,ENSAYOS!$Q$5:$Q$3004,">0",ENSAYOS!$G$5:$G$3004,">="&CONFIG!$B$27))) | W19: =IF(AND(U19<>"",V19<>""),U19/V19,"") | X19: =IF(U19="","",INDEX('CURVA EDAD'!$E$5:$E$32,MIN(28,MAX(1,N19)))) -> 0.84 | Y19: =IF(V19<>"",V19,IF(U19="","",U19/X19)) -> 84.837947 | Z19: =IF(V19<>"",_xlfn.MINIFS(ENSAYOS!$Q$5:$Q$3004,ENSAYOS!$C$5:$C$3004,F19,ENSAYOS!$Q$5:$Q$3004,">0",ENSAYOS!$G$5:$G$3004,">="&CONFIG!$B$27),IF(U19="","",_xlfn.MINIFS(ENSAYOS!$Q$5:$Q$3004,ENSAYOS!$C$5:$C$3004,F19,ENSAYOS!$Q$5:$Q$3004,">0",ENSAYOS!$G$5:$G$3004,N19)/X19)) -> 76.436222 | AA19: =IF(D19="","",IFERROR(1/(1/INDEX(CONFIG!$J$5:$J$14,MATCH(D19,CONFIG!$D$5:$D$14,0))),"")) | AB19: =IF(D19="","",IFERROR(1/(1/INDEX(CONFIG!$K$5:$K$14,MATCH(D19,CONFIG!$D$5:$D$14,0))),"")) | AC19: =IF(N(M19)=0,"",IF(AA19="","Sin spec",IF(AND(Y19>=AA19,OR(AB19="",Z19>=AB19)),"CUMPLE","NO CUMPLE")&IF(V19=""," (est.)",""))) -> Sin spec | AD19: =IF(F19="","",IF(COUNTIFS(ABSORCION!$C$5:$C$1004,F19,ABSORCION!$I$5:$I$1004,">0")=0,"",AVERAGEIFS(ABSORCION!$I$5:$I$1004,ABSORCION!$C$5:$C$1004,F19,ABSORCION!$I$5:$I$1004,">0"))) | AE19: =IF(F19="","",IF(COUNTIFS(ABSORCION!$C$5:$C$1004,F19,ABSORCION!$I$5:$I$1004,">0")=0,"",AVERAGEIFS(ABSORCION!$K$5:$K$1004,ABSORCION!$C$5:$C$1004,F19,ABSORCION!$I$5:$I$1004,">0"))) | AF19: =IF(AE19="","",IF(AE19>=CONFIG!$E$21,CONFIG!$F$21,IF(AE19>=CONFIG!$E$20,CONFIG!$F$20,CONFIG!$F$19))) | AG19: =IF(F19="","",TRIM(IF(N(M19)=0,"Sin ensayos. ","")&IF(AND(N(M19)>0,N(M19)<CONFIG!$B$26),"Menos de "&CONFIG!$B$26&" probetas. ","")&IF(N(T19)>CONFIG!$B$25,"CV alto. ","")&IF(AND(N(AD19)>0,N(AD19)>N(AF19)),"Absorción alta. ",""))) | AH19: =IF(AND(N(M19)>0,OR(CONTROL!$C$4="TODAS",C19=CONTROL!$C$4),D19=CONTROL!$C$5),MAX($AH$4:AH18)+1,"") -> 12 | AI19: =IF(AH19="","",P19^2) -> 5078.5399
A20: =IF(B20="","",ROW()-4) -> 16 | B20: 45707 | C20: P1 | D20: Block 8" | F20: =IF(OR(B20="",C20="",D20=""),"",IFERROR(INDEX(CONFIG!$E$5:$E$14,MATCH(D20,CONFIG!$D$5:$D$14,0)),"?")&RIGHT("0"&DAY(B20),2)&RIGHT("0"&MONTH(B20),2)&RIGHT(YEAR(B20),2)&C20&IF(E20="","","-"&E20)) -> 8190225P1 | M20: =IF(F20="","",COUNTIFS(ENSAYOS!$C$5:$C$3004,F20,ENSAYOS!$Q$5:$Q$3004,">0")) -> 4 | N20: =IF(N(M20)=0,"",_xlfn.MINIFS(ENSAYOS!$G$5:$G$3004,ENSAYOS!$C$5:$C$3004,F20,ENSAYOS!$Q$5:$Q$3004,">0")) -> 9 | O20: =IF(N(M20)=0,"",_xlfn.MAXIFS(ENSAYOS!$G$5:$G$3004,ENSAYOS!$C$5:$C$3004,F20,ENSAYOS!$Q$5:$Q$3004,">0")) -> 9 | P20: =IF(N(M20)=0,"",AVERAGEIFS(ENSAYOS!$Q$5:$Q$3004,ENSAYOS!$C$5:$C$3004,F20,ENSAYOS!$Q$5:$Q$3004,">0")) -> 77.501461 | Q20: =IF(N(M20)=0,"",_xlfn.MINIFS(ENSAYOS!$Q$5:$Q$3004,ENSAYOS!$C$5:$C$3004,F20,ENSAYOS!$Q$5:$Q$3004,">0")) -> 69.535865 | R20: =IF(N(M20)=0,"",_xlfn.MAXIFS(ENSAYOS!$Q$5:$Q$3004,ENSAYOS!$C$5:$C$3004,F20,ENSAYOS!$Q$5:$Q$3004,">0")) -> 82.584875 | S20: =IF(N(M20)<2,"",SQRT(MAX(0,(SUMIFS(ENSAYOS!$X$5:$X$3004,ENSAYOS!$C$5:$C$3004,F20,ENSAYOS!$Q$5:$Q$3004,">0")-M20*P20^2)/(M20-1)))) -> 5.6504169 | T20: =IF(S20="","",S20/P20) -> 0.072907232 | U20: =IF(N(M20)=0,"",IF(N20>=CONFIG!$B$27,"",AVERAGEIFS(ENSAYOS!$Q$5:$Q$3004,ENSAYOS!$C$5:$C$3004,F20,ENSAYOS!$Q$5:$Q$3004,">0",ENSAYOS!$G$5:$G$3004,N20))) -> 77.501461 | V20: =IF(N(M20)=0,"",IF(COUNTIFS(ENSAYOS!$C$5:$C$3004,F20,ENSAYOS!$Q$5:$Q$3004,">0",ENSAYOS!$G$5:$G$3004,">="&CONFIG!$B$27)=0,"",AVERAGEIFS(ENSAYOS!$Q$5:$Q$3004,ENSAYOS!$C$5:$C$3004,F20,ENSAYOS!$Q$5:$Q$3004,">0",ENSAYOS!$G$5:$G$3004,">="&CONFIG!$B$27))) | W20: =IF(AND(U20<>"",V20<>""),U20/V20,"") | X20: =IF(U20="","",INDEX('CURVA EDAD'!$E$5:$E$32,MIN(28,MAX(1,N20)))) -> 0.924 | Y20: =IF(V20<>"",V20,IF(U20="","",U20/X20)) -> 83.87604 | Z20: =IF(V20<>"",_xlfn.MINIFS(ENSAYOS!$Q$5:$Q$3004,ENSAYOS!$C$5:$C$3004,F20,ENSAYOS!$Q$5:$Q$3004,">0",ENSAYOS!$G$5:$G$3004,">="&CONFIG!$B$27),IF(U20="","",_xlfn.MINIFS(ENSAYOS!$Q$5:$Q$3004,ENSAYOS!$C$5:$C$3004,F20,ENSAYOS!$Q$5:$Q$3004,">0",ENSAYOS!$G$5:$G$3004,N20)/X20)) -> 75.255265 | AA20: =IF(D20="","",IFERROR(1/(1/INDEX(CONFIG!$J$5:$J$14,MATCH(D20,CONFIG!$D$5:$D$14,0))),"")) | AB20: =IF(D20="","",IFERROR(1/(1/INDEX(CONFIG!$K$5:$K$14,MATCH(D20,CONFIG!$D$5:$D$14,0))),"")) | AC20: =IF(N(M20)=0,"",IF(AA20="","Sin spec",IF(AND(Y20>=AA20,OR(AB20="",Z20>=AB20)),"CUMPLE","NO CUMPLE")&IF(V20=""," (est.)",""))) -> Sin spec | AD20: =IF(F20="","",IF(COUNTIFS(ABSORCION!$C$5:$C$1004,F20,ABSORCION!$I$5:$I$1004,">0")=0,"",AVERAGEIFS(ABSORCION!$I$5:$I$1004,ABSORCION!$C$5:$C$1004,F20,ABSORCION!$I$5:$I$1004,">0"))) | AE20: =IF(F20="","",IF(COUNTIFS(ABSORCION!$C$5:$C$1004,F20,ABSORCION!$I$5:$I$1004,">0")=0,"",AVERAGEIFS(ABSORCION!$K$5:$K$1004,ABSORCION!$C$5:$C$1004,F20,ABSORCION!$I$5:$I$1004,">0"))) | AF20: =IF(AE20="","",IF(AE20>=CONFIG!$E$21,CONFIG!$F$21,IF(AE20>=CONFIG!$E$20,CONFIG!$F$20,CONFIG!$F$19))) | AG20: =IF(F20="","",TRIM(IF(N(M20)=0,"Sin ensayos. ","")&IF(AND(N(M20)>0,N(M20)<CONFIG!$B$26),"Menos de "&CONFIG!$B$26&" probetas. ","")&IF(N(T20)>CONFIG!$B$25,"CV alto. ","")&IF(AND(N(AD20)>0,N(AD20)>N(AF20)),"Absorción alta. ",""))) | AH20: =IF(AND(N(M20)>0,OR(CONTROL!$C$4="TODAS",C20=CONTROL!$C$4),D20=CONTROL!$C$5),MAX($AH$4:AH19)+1,"") -> 13 | AI20: =IF(AH20="","",P20^2) -> 6006.4764
A21: =IF(B21="","",ROW()-4) -> 17 | B21: 45709 | C21: P2 | D21: Block 6" | F21: =IF(OR(B21="",C21="",D21=""),"",IFERROR(INDEX(CONFIG!$E$5:$E$14,MATCH(D21,CONFIG!$D$5:$D$14,0)),"?")&RIGHT("0"&DAY(B21),2)&RIGHT("0"&MONTH(B21),2)&RIGHT(YEAR(B21),2)&C21&IF(E21="","","-"&E21)) -> 6210225P2 | M21: =IF(F21="","",COUNTIFS(ENSAYOS!$C$5:$C$3004,F21,ENSAYOS!$Q$5:$Q$3004,">0")) -> 4 | N21: =IF(N(M21)=0,"",_xlfn.MINIFS(ENSAYOS!$G$5:$G$3004,ENSAYOS!$C$5:$C$3004,F21,ENSAYOS!$Q$5:$Q$3004,">0")) -> 5 | O21: =IF(N(M21)=0,"",_xlfn.MAXIFS(ENSAYOS!$G$5:$G$3004,ENSAYOS!$C$5:$C$3004,F21,ENSAYOS!$Q$5:$Q$3004,">0")) -> 5 | P21: =IF(N(M21)=0,"",AVERAGEIFS(ENSAYOS!$Q$5:$Q$3004,ENSAYOS!$C$5:$C$3004,F21,ENSAYOS!$Q$5:$Q$3004,">0")) -> 65.030554 | Q21: =IF(N(M21)=0,"",_xlfn.MINIFS(ENSAYOS!$Q$5:$Q$3004,ENSAYOS!$C$5:$C$3004,F21,ENSAYOS!$Q$5:$Q$3004,">0")) -> 61.026626 | R21: =IF(N(M21)=0,"",_xlfn.MAXIFS(ENSAYOS!$Q$5:$Q$3004,ENSAYOS!$C$5:$C$3004,F21,ENSAYOS!$Q$5:$Q$3004,">0")) -> 74.664339 | S21: =IF(N(M21)<2,"",SQRT(MAX(0,(SUMIFS(ENSAYOS!$X$5:$X$3004,ENSAYOS!$C$5:$C$3004,F21,ENSAYOS!$Q$5:$Q$3004,">0")-M21*P21^2)/(M21-1)))) -> 6.4469342 | T21: =IF(S21="","",S21/P21) -> 0.099137003 | U21: =IF(N(M21)=0,"",IF(N21>=CONFIG!$B$27,"",AVERAGEIFS(ENSAYOS!$Q$5:$Q$3004,ENSAYOS!$C$5:$C$3004,F21,ENSAYOS!$Q$5:$Q$3004,">0",ENSAYOS!$G$5:$G$3004,N21))) -> 65.030554 | V21: =IF(N(M21)=0,"",IF(COUNTIFS(ENSAYOS!$C$5:$C$3004,F21,ENSAYOS!$Q$5:$Q$3004,">0",ENSAYOS!$G$5:$G$3004,">="&CONFIG!$B$27)=0,"",AVERAGEIFS(ENSAYOS!$Q$5:$Q$3004,ENSAYOS!$C$5:$C$3004,F21,ENSAYOS!$Q$5:$Q$3004,">0",ENSAYOS!$G$5:$G$3004,">="&CONFIG!$B$27))) | W21: =IF(AND(U21<>"",V21<>""),U21/V21,"") | X21: =IF(U21="","",INDEX('CURVA EDAD'!$E$5:$E$32,MIN(28,MAX(1,N21)))) -> 0.89 | Y21: =IF(V21<>"",V21,IF(U21="","",U21/X21)) -> 73.068039 | Z21: =IF(V21<>"",_xlfn.MINIFS(ENSAYOS!$Q$5:$Q$3004,ENSAYOS!$C$5:$C$3004,F21,ENSAYOS!$Q$5:$Q$3004,">0",ENSAYOS!$G$5:$G$3004,">="&CONFIG!$B$27),IF(U21="","",_xlfn.MINIFS(ENSAYOS!$Q$5:$Q$3004,ENSAYOS!$C$5:$C$3004,F21,ENSAYOS!$Q$5:$Q$3004,">0",ENSAYOS!$G$5:$G$3004,N21)/X21)) -> 68.569243 | AA21: =IF(D21="","",IFERROR(1/(1/INDEX(CONFIG!$J$5:$J$14,MATCH(D21,CONFIG!$D$5:$D$14,0))),"")) | AB21: =IF(D21="","",IFERROR(1/(1/INDEX(CONFIG!$K$5:$K$14,MATCH(D21,CONFIG!$D$5:$D$14,0))),"")) | AC21: =IF(N(M21)=0,"",IF(AA21="","Sin spec",IF(AND(Y21>=AA21,OR(AB21="",Z21>=AB21)),"CUMPLE","NO CUMPLE")&IF(V21=""," (est.)",""))) -> Sin spec | AD21: =IF(F21="","",IF(COUNTIFS(ABSORCION!$C$5:$C$1004,F21,ABSORCION!$I$5:$I$1004,">0")=0,"",AVERAGEIFS(ABSORCION!$I$5:$I$1004,ABSORCION!$C$5:$C$1004,F21,ABSORCION!$I$5:$I$1004,">0"))) | AE21: =IF(F21="","",IF(COUNTIFS(ABSORCION!$C$5:$C$1004,F21,ABSORCION!$I$5:$I$1004,">0")=0,"",AVERAGEIFS(ABSORCION!$K$5:$K$1004,ABSORCION!$C$5:$C$1004,F21,ABSORCION!$I$5:$I$1004,">0"))) | AF21: =IF(AE21="","",IF(AE21>=CONFIG!$E$21,CONFIG!$F$21,IF(AE21>=CONFIG!$E$20,CONFIG!$F$20,CONFIG!$F$19))) | AG21: =IF(F21="","",TRIM(IF(N(M21)=0,"Sin ensayos. ","")&IF(AND(N(M21)>0,N(M21)<CONFIG!$B$26),"Menos de "&CONFIG!$B$26&" probetas. ","")&IF(N(T21)>CONFIG!$B$25,"CV alto. ","")&IF(AND(N(AD21)>0,N(AD21)>N(AF21)),"Absorción alta. ",""))) | AH21: =IF(AND(N(M21)>0,OR(CONTROL!$C$4="TODAS",C21=CONTROL!$C$4),D21=CONTROL!$C$5),MAX($AH$4:AH20)+1,"") | AI21: =IF(AH21="","",P21^2)
